Workbook
Name aa: 'Orig data'!$B$1
Name ar: #REF!
Name ar: #REF!
Name bb: 'Orig data'!$B$2
Name br: #REF!
Name br: #REF!
Name cslope: 'Orig data'!$AW$3
Name negLL: #REF!
Name negLL: #REF!
Name nlim: 'Orig data'!$AY$3
Name retroU: 'Orig data'!$AQ$2
Name retroUtil: 'Orig data'!$BA$1
Name retroY: 'Orig data'!$AQ$3
Name rho: #REF!
Name rho: #REF!
Name sige: #REF!
Name sige: #REF!
Name sigev: #REF!
Name sigev: #REF!
Name sigr: #REF!
Name sigr: #REF!
Name umethod: 'Orig data'!$AU$2

Sheet Orig data
A1: aa | B1: =INTERCEPT(J5:J71,H5:H71) -> 1.129053 | C1: smsy | D1: =aa/bb*(1-0.07*aa) -> 1688967.4 | E1: Nmsy | F1: =D1/(1-D2) -> 3218878.6 | W1: Age 3 | X1: Age 4 | Y1: Age 5 | Z1: Age 6 | AM1: retrtospective model in columns AJ-AO | AT1: switch between historical and policy-based Ut values: | AZ1: retroUtil | BA1: =SUMPRODUCT(AR5:AR76^0.6) -> 226111.37 | BC1: C 1997-2022 | BD1: =SUM(U51:U76) -> 8311103.8 | BE1: recent loss | BF1: =BD2-BD1 -> 11475187 | BH1: =500000/24000 -> 20.833333
A2: bb | B2: =-SLOPE(J5:J71,H5:H71) -> 6.1565412e-07 | C2: umsy | D2: =0.5*aa-0.07*aa^2 -> 0.47529324 | E2: msy | F2: =F1-D1 -> 1529911.2 | H2: Best S-R data | W2: 0.3 | X2: 0.6 | Y2: 0.1 | Z2: 0 | AP2: retroU | AQ2: 0.5 | AT2: Ut method | AU2: 2 | AV2: 1=historical,2=retroU,3=linear hcr | AZ2: =retroY -> 51361535 | BA2: =retroUtil -> 226111.37 | BC2: retro C 1990+ | BD2: =SUM(AR51:AR76) -> 19786290 | BE2: income loss | BF2: =BF1*12 -> 1.3770224e+08
A3: Cass, Grant, Digitized, Haley's S/R | F3: ssl M 2017 | G3: =0.0000345*G71 -> 1.4193275 | H3: Using age prop. by yr from 1996-2017 | L3: Haley's Best S/R | W3: recruits produced at age from Brood Year | AP3: retroY | AQ3: =SUM(AR5:AR76) -> 51361535 | AR3: historical Y | AS3: =SUM(S5:S76)-SUM(H5:H76) -> 26625164 | AU3: linear hcr pars | AV3: cslope | AW3: 0.77633553 | AX3: nlim | AY3: 487692.73 | BB3: Johnstone | BC3: Georgia. | BD3: West | BF3: U.S. | BG3: All Fraser | BH3: Total | BI3: Harvest | BJ3: Gross (d) | BK3: Total | BM3: Johnstone | BN3: West Coast | BS3: Johnstone | BT3: West Coast
A4: Source | B4: Brood year | C4: Spawners (D) | D4: Haley's Recruits with some infill from mkm | E4: ln(R/S)(H) | F4: Source | G4: SSL numbers | H4: Spawners (D) | I4: Recruits | J4: ln(R/S)(D) | K4: wt | L4: broodyear | M4: spawners | N4: recruits | P4: Source | Q4: Year | R4: Gross Escapement | S4: total Stock, hr from Grant then Brittany | T4: Historial Ut | U4: Historical Catch | V4: tot stock digitized from DFO 2023 | W4: Age 3 | X4: Age 4 | Y4: Age 5 | Z4: Age 6 | AA4: Recruits sum age | AF4: Improved recruits starting 1990 | AG4: brood year | AH4: rp3 | AI4: rp4 | AJ4: rp5 | AL4: retro rec alt formula | AM4: year | AN4: retro run | AO4: retro U | AP4: retro spawners | AQ4: retro Recruits | AR4: retro Yield | AZ4: Source | BA4: Year | BB4: Strait (a) | BC4: Strait | BD4: Coast (b) | BE4: 7&7A | BF4: 4B,5,6C | BG4: Harvest (c) | BH4: Harvest | BI4: Rate | BJ4: Escapement | BK4: Stock | BL4: HR | BM4: St. HR | BN4: HR | BO4: Fraser R HR | BP4: hr | BQ4: catch | BS4: St. HR | BT4: HR | BU4: Fraser R HR
A5: =P5 -> Cass | B5: =L5 -> 1951 | C5: =M5 -> 171725 | D5: =N5 -> 498986 | E5: =LN(D5/C5) -> 1.0666837 | F5: =A5 -> Cass | G5: 17243.254 | H5: =R5 -> 171725 | I5: =AA5 -> 595477.2 | J5: =LN(I5/H5) -> 1.2434687 | K5: =J5-(aa-bb*H5) -> 0.22013898 | L5: 1951 | M5: 171725 | N5: 498986 | P5: =AZ5 -> Cass | Q5: =BA5 -> 1951 | R5: =BJ5 -> 171725 | S5: =BK5 -> 1187739 | T5: =1-R5/S5 -> 0.85541857 | U5: =S5-R5 -> 1016014 | W5: =$S8*W$2 -> 328955.1 | X5: =$S9*X$2 -> 238259.4 | Y5: =$S10*Y$2 -> 28262.7 | Z5: =$S11*Z$2 -> 0 | AA5: =SUM(W5:Z5) -> 595477.2 | AF5: =AA5 -> 595477.2 | AG5: =B5 -> 1951 | AH5: =W5/$AA5 -> 0.55242266 | AI5: =X5/$AA5 -> 0.40011507 | AJ5: =Y5/$AA5 -> 0.047462271 | AL5: =I5*AP5/H5*EXP(-bb*(AP5-H5)) -> 1588004.3 | AM5: =B5 -> 1951 | AN5: =S5 -> 1187739 | AO5: =CHOOSE(umethod,T5,retroU,MAX(0,cslope*(AN5-nlim)/AN5)) -> 0.5 | AP5: =AN5*(1-AO5) -> 593869.5 | AQ5: =AP5*EXP(aa-bb*AP5+K5) -> 1588004.3 | AR5: =AN5-AP5 -> 593869.5 | AZ5: Cass | BA5: 1951 | BB5: 523874 | BC5: N/A | BD5: 302 | BE5: 0 | BF5: 23 | BG5: 491815 | BH5: 1016014 | BI5: 0.86 | BJ5: 171725 | BK5: 1187739 | BL5: =BH5/BK5 -> 0.85541857 | BM5: =BB5/BK5 -> 0.44106828 | BN5: =BD5/(BK5-BB5) -> 0.00045491177 | BO5: =BG5/(BK5-BB5-BD5-BF5) -> 0.74119872 | BP5: =BH5/BK5 -> 0.85541857 | BQ5: =BJ5*BP5/(1-BP5) -> 1016014 | BS5: =BM5/(SUM($BM5:$BO5)) -> 0.37292645 | BT5: =BN5/(SUM($BM5:$BO5)) -> 0.00038463121 | BU5: =BO5/(SUM($BM5:$BO5)) -> 0.62668892 | CR5: Grant vs. Cass
A6: =P6 -> Cass | B6: =L6 -> 1952 | C6: =M6 -> 176250 | D6: =N6 -> 283055 | E6: =LN(D6/C6) -> 0.47373778 | F6: =A6 -> Cass | G6: 17747.773 | H6: =R6 -> 176250 | I6: =AA6 -> 319542.2 | J6: =LN(I6/H6) -> 0.5949859 | K6: =J6-(aa-bb*H6) -> -0.42555802 | L6: 1952 | M6: 176250 | N6: 283055 | P6: =AZ6 -> Cass | Q6: =BA6 -> 1952 | R6: =BJ6 -> 176250 | S6: =BK6 -> 927000 | T6: =1-R6/S6 -> 0.80987055 | U6: =S6-R6 -> 750750 | W6: =$S9*W$2 -> 119129.7 | X6: =$S10*X$2 -> 169576.2 | Y6: =$S11*Y$2 -> 30836.3 | Z6: =$S12*Z$2 -> 0 | AA6: =SUM(W6:Z6) -> 319542.2 | AF6: =AA6 -> 319542.2 | AG6: =B6 -> 1952 | AH6: =W6/$AA6 -> 0.37281367 | AI6: =X6/$AA6 -> 0.53068484 | AJ6: =Y6/$AA6 -> 0.096501495 | AL6: =I6*AP6/H6*EXP(-bb*(AP6-H6)) -> 704117.78 | AM6: =B6 -> 1952 | AN6: =S6 -> 927000 | AO6: =CHOOSE(umethod,T6,retroU,MAX(0,cslope*(AN6-nlim)/AN6)) -> 0.5 | AP6: =AN6*(1-AO6) -> 463500 | AQ6: =AP6*EXP(aa-bb*AP6+K6) -> 704117.78 | AR6: =AN6-AP6 -> 463500 | AV6: =retroY -> 51361535 | AZ6: Cass | BA6: 1952 | BB6: 191249 | BC6: N/A | BD6: 108 | BE6: 0 | BF6: 0 | BG6: 559393 | BH6: 750750 | BI6: 0.81 | BJ6: 176250 | BK6: 927000 | BL6: =BH6/BK6 -> 0.80987055 | BM6: =BB6/BK6 -> 0.2063096 | BN6: =BD6/(BK6-BB6) -> 0.00014678879 | BO6: =BG6/(BK6-BB6-BD6-BF6) -> 0.76041368 | BP6: =BH6/BK6 -> 0.80987055 | BQ6: =BJ6*BP6/(1-BP6) -> 750750 | BS6: =BM6/(SUM($BM6:$BO6)) -> 0.21337883 | BT6: =BN6/(SUM($BM6:$BO6)) -> 0.00015181853 | BU6: =BO6/(SUM($BM6:$BO6)) -> 0.78646935 | CE6: Source | CF6: Year | CG6: Total Returns | CH6: Areas 11 to 13 | CI6: Area 14 | CJ6: Areas 20 & 21 | CK6: Areas 7 & 7a | CL6: Areas 4b, 5, 6c | CM6: Fraser | CN6: Gross Escapement | CO6: Gross Esc+catch | CQ6: Total exploitation rate | CR6: Year | CS6: %dif tot returns | CT6: %dif gross escape
A7: =P7 -> Grant | B7: =L7 -> 1953 | C7: =M7 -> 137225 | D7: =N7 -> 312122 | E7: =LN(D7/C7) -> 0.82177222 | F7: =A7 -> Grant | G7: 18200.243 | H7: =R7 -> 137625 | I7: =AA7 -> 325788.8 | J7: =LN(I7/H7) -> 0.86171672 | K7: =J7-(aa-bb*H7) -> -0.18260684 | L7: 1953 | M7: 137225 | N7: 312122 | P7: =CE7 -> Grant | Q7: =CF7 -> 1953 | R7: =CN7 -> 137625 | S7: =CG7 -> 918122 | T7: =1-R7/S7 -> 0.85010162 | U7: =S7-R7 -> 780497 | W7: =$S10*W$2 -> 84788.1 | X7: =$S11*X$2 -> 185017.8 | Y7: =$S12*Y$2 -> 55982.9 | Z7: =$S13*Z$2 -> 0 | AA7: =SUM(W7:Z7) -> 325788.8 | AF7: =AA7 -> 325788.8 | AG7: =B7 -> 1953 | AH7: =W7/$AA7 -> 0.2602548 | AI7: =X7/$AA7 -> 0.56790718 | AJ7: =Y7/$AA7 -> 0.17183801 | AL7: =I7*AP7/H7*EXP(-bb*(AP7-H7)) -> 891590.03 | AM7: =B7 -> 1953 | AN7: =S7 -> 918122 | AO7: =CHOOSE(umethod,T7,retroU,MAX(0,cslope*(AN7-nlim)/AN7)) -> 0.5 | AP7: =AN7*(1-AO7) -> 459061 | AQ7: =AP7*EXP(aa-bb*AP7+K7) -> 891590.03 | AR7: =AN7-AP7 -> 459061 | AU7: 0.05 | AV7: 6404262.3 | AZ7: Cass | BA7: 1953 | BB7: 465021 | BC7: N/A | BD7: 404 | BE7: 0 | BF7: 0 | BG7: 331804 | BH7: 797229 | BI7: 0.85 | BJ7: 137225 | BK7: 934454 | BL7: =BH7/BK7 -> 0.85314954 | BM7: =BB7/BK7 -> 0.49763926 | BN7: =BD7/(BK7-BB7) -> 0.0008606127 | BO7: =BG7/(BK7-BB7-BD7-BF7) -> 0.70742747 | BP7: =BH7/BK7 -> 0.85314954 | BQ7: =BJ7*BP7/(1-BP7) -> 797229 | BS7: =BM7/(SUM($BM7:$BO7)) -> 0.41266106 | BT7: =BN7/(SUM($BM7:$BO7)) -> 0.00071365219 | BU7: =BO7/(SUM($BM7:$BO7)) -> 0.58662528 | CE7: Grant | CF7: 1953 | CG7: 918122 | CH7: 434551 | CI7: 10184 | CJ7: 3947 | CK7: 0 | CL7: 0 | CM7: 331815 | CN7: 137625 | CO7: =SUM(CH7:CN7) -> 918122 | CQ7: 0.85 | CR7: =CF7 -> 1953 | CS7: =(CG7-BK7)/BK7 -> -0.017477586 | CT7: =(CN7-BJ7)/BJ7 -> 0.0029149208
A8: =P8 -> Grant | B8: =L8 -> 1954 | C8: =M8 -> 86375 | D8: =N8 -> 504589 | E8: =LN(D8/C8) -> 1.765046 | F8: =A8 -> Grant | G8: 18877.276 | H8: =R8 -> 86375 | I8: =AA8 -> 493568.5 | J8: =LN(I8/H8) -> 1.7429634 | K8: =J8-(aa-bb*H8) -> 0.66708753 | L8: 1954 | M8: 86375 | N8: 504589 | P8: =CE8 -> Grant | Q8: =CF8 -> 1954 | R8: =CN8 -> 86375 | S8: =CG8 -> 1096517 | T8: =1-R8/S8 -> 0.92122785 | U8: =S8-R8 -> 1010142 | W8: =$S11*W$2 -> 92508.9 | X8: =$S12*X$2 -> 335897.4 | Y8: =$S13*Y$2 -> 65162.2 | Z8: =$S14*Z$2 -> 0 | AA8: =SUM(W8:Z8) -> 493568.5 | AF8: =AA8 -> 493568.5 | AG8: =B8 -> 1954 | AH8: =W8/$AA8 -> 0.1874287 | AI8: =X8/$AA8 -> 0.6805487 | AJ8: =Y8/$AA8 -> 0.13202261 | AL8: =I8*AP8/H8*EXP(-bb*(AP8-H8)) -> 2357483 | AM8: =B8 -> 1954 | AN8: =S8 -> 1096517 | AO8: =CHOOSE(umethod,T8,retroU,MAX(0,cslope*(AN8-nlim)/AN8)) -> 0.5 | AP8: =AN8*(1-AO8) -> 548258.5 | AQ8: =AP8*EXP(aa-bb*AP8+K8) -> 2357483 | AR8: =AN8-AP8 -> 548258.5 | AU8: 0.1 | AV8: 12808818 | AZ8: Cass | BA8: 1954 | BB8: 590473 | BC8: N/A | BD8: 253 | BE8: 0 | BF8: 0 | BG8: 457750 | BH8: 1048476 | BI8: 0.92 | BJ8: 86375 | BK8: 1134851 | BL8: =BH8/BK8 -> 0.92388869 | BM8: =BB8/BK8 -> 0.52030883 | BN8: =BD8/(BK8-BB8) -> 0.0004647506 | BO8: =BG8/(BK8-BB8-BD8-BF8) -> 0.8412589 | BP8: =BH8/BK8 -> 0.92388869 | BQ8: =BJ8*BP8/(1-BP8) -> 1048476 | BS8: =BM8/(SUM($BM8:$BO8)) -> 0.38200912 | BT8: =BN8/(SUM($BM8:$BO8)) -> 0.00034121844 | BU8: =BO8/(SUM($BM8:$BO8)) -> 0.61764966 | CE8: Grant | CF8: 1954 | CG8: 1096517 | CH8: 542719 | CI8: 8768 | CJ8: 1248 | CK8: 0 | CL8: 0 | CM8: 457407 | CN8: 86375 | CO8: =SUM(CH8:CN8) -> 1096517 | CQ8: 0.921 | CR8: =CF8 -> 1954 | CS8: =(CG8-BK8)/BK8 -> -0.033778884 | CT8: =(CN8-BJ8)/BJ8 -> 0
A9: =P9 -> Grant | B9: =L9 -> 1955 | C9: =M9 -> 110500 | D9: =N9 -> 592568 | E9: =LN(D9/C9) -> 1.6794501 | F9: =A9 -> Grant | G9: 19634.011 | H9: =R9 -> 110500 | I9: =AA9 -> 597993.3 | J9: =LN(I9/H9) -> 1.688564 | K9: =J9-(aa-bb*H9) -> 0.62754085 | L9: 1955 | M9: 110500 | N9: 592568 | P9: =CE9 -> Grant | Q9: =CF9 -> 1955 | R9: =CN9 -> 110500 | S9: =CG9 -> 397099 | T9: =1-R9/S9 -> 0.72173186 | U9: =S9-R9 -> 286599 | W9: =$S12*W$2 -> 167948.7 | X9: =$S13*X$2 -> 390973.2 | Y9: =$S14*Y$2 -> 39071.4 | Z9: =$S15*Z$2 -> 0 | AA9: =SUM(W9:Z9) -> 597993.3 | AF9: =AA9 -> 597993.3 | AG9: =B9 -> 1955 | AH9: =W9/$AA9 -> 0.28085382 | AI9: =X9/$AA9 -> 0.65380866 | AJ9: =Y9/$AA9 -> 0.065337521 | AL9: =I9*AP9/H9*EXP(-bb*(AP9-H9)) -> 1972582.1 | AM9: =B9 -> 1955 | AN9: =AH6*AQ6+AI5*AQ5 -> 897889.17 | AO9: =CHOOSE(umethod,T9,retroU,MAX(0,cslope*(AN9-nlim)/AN9)) -> 0.5 | AP9: =AN9*(1-AO9) -> 448944.59 | AQ9: =AP9*EXP(aa-bb*AP9+K9) -> 1972582.1 | AR9: =AN9-AP9 -> 448944.59 | AU9: 0.15 | AV9: 19166297 | AZ9: Cass | BA9: 1955 | BB9: 143565 | BC9: N/A | BD9: 759 | BE9: 0 | BF9: 9 | BG9: 103297 | BH9: 247630 | BI9: 0.69 | BJ9: 110500 | BK9: 358130 | BL9: =BH9/BK9 -> 0.69145282 | BM9: =BB9/BK9 -> 0.40087398 | BN9: =BD9/(BK9-BB9) -> 0.0035373896 | BO9: =BG9/(BK9-BB9-BD9-BF9) -> 0.48315458 | BP9: =BH9/BK9 -> 0.69145282 | BQ9: =BJ9*BP9/(1-BP9) -> 247630 | BS9: =BM9/(SUM($BM9:$BO9)) -> 0.45165543 | BT9: =BN9/(SUM($BM9:$BO9)) -> 0.0039854949 | BU9: =BO9/(SUM($BM9:$BO9)) -> 0.54435907 | CE9: Grant | CF9: 1955 | CG9: 397099 | CH9: 174665 | CI9: 634 | CJ9: 8217 | CK9: 0 | CL9: 0 | CM9: 103084 | CN9: 110500 | CO9: =SUM(CH9:CN9) -> 397100 | CQ9: 0.722 | CR9: =CF9 -> 1955 | CS9: =(CG9-BK9)/BK9 -> 0.10881244 | CT9: =(CN9-BJ9)/BJ9 -> 0
A10: =P10 -> Grant | B10: =L10 -> 1956 | C10: =M10 -> 32925 | D10: =N10 -> 518932 | E10: =LN(D10/C10) -> 2.7575406 | F10: =A10 -> Grant | G10: 20266.027 | H10: =R10 -> 32950 | I10: =AA10 -> 455279.4 | J10: =LN(I10/H10) -> 2.62592 | K10: =J10-(aa-bb*H10) -> 1.5171529 | L10: 1956 | M10: 32925 | N10: 518932 | P10: =CE10 -> Grant | Q10: =CF10 -> 1956 | R10: =CN10 -> 32950 | S10: =CG10 -> 282627 | T10: =1-R10/S10 -> 0.88341524 | U10: =S10-R10 -> 249677 | W10: =$S13*W$2 -> 195486.6 | X10: =$S14*X$2 -> 234428.4 | Y10: =$S15*Y$2 -> 25364.4 | Z10: =$S16*Z$2 -> 0 | AA10: =SUM(W10:Z10) -> 455279.4 | AF10: =AA10 -> 455279.4 | AG10: =B10 -> 1956 | AH10: =W10/$AA10 -> 0.42937721 | AI10: =X10/$AA10 -> 0.51491106 | AJ10: =Y10/$AA10 -> 0.055711723 | AL10: =I10*AP10/H10*EXP(-bb*(AP10-H10)) -> 3893556.8 | AM10: =B10 -> 1956 | AN10: =AH7*AQ7+AI6*AQ6+AJ5*AQ5 -> 681075.51 | AO10: =CHOOSE(umethod,T10,retroU,MAX(0,cslope*(AN10-nlim)/AN10)) -> 0.5 | AP10: =AN10*(1-AO10) -> 340537.75 | AQ10: =AP10*EXP(aa-bb*AP10+K10) -> 3893556.8 | AR10: =AN10-AP10 -> 340537.75 | AU10: 0.2 | AV10: 25410624 | AZ10: Cass | BA10: 1956 | BB10: 155668 | BC10: N/A | BD10: 61 | BE10: 0 | BF10: 0 | BG10: 72958 | BH10: 228687 | BI10: 0.87 | BJ10: 32925 | BK10: 261612 | BL10: =BH10/BK10 -> 0.87414568 | BM10: =BB10/BK10 -> 0.59503387 | BN10: =BD10/(BK10-BB10) -> 0.00057577588 | BO10: =BG10/(BK10-BB10-BD10-BF10) -> 0.68904357 | BP10: =BH10/BK10 -> 0.87414568 | BQ10: =BJ10*BP10/(1-BP10) -> 228687 | BS10: =BM10/(SUM($BM10:$BO10)) -> 0.46318638 | BT10: =BN10/(SUM($BM10:$BO10)) -> 0.00044819557 | BU10: =BO10/(SUM($BM10:$BO10)) -> 0.53636543 | CE10: Grant | CF10: 1956 | CG10: 282627 | CH10: 175589 | CI10: 685 | CJ10: 591 | CK10: 0 | CL10: 0 | CM10: 72812 | CN10: 32950 | CO10: =SUM(CH10:CN10) -> 282627 | CQ10: 0.883 | CR10: =CF10 -> 1956 | CS10: =(CG10-BK10)/BK10 -> 0.080328884 | CT10: =(CN10-BJ10)/BJ10 -> 0.00075930144
A11: =P11 -> Grant | B11: =L11 -> 1957 | C11: =M11 -> 84630 | D11: =N11 -> 353281 | E11: =LN(D11/C11) -> 1.428975 | F11: =A11 -> Grant | G11: 20594.875 | H11: =R11 -> 84655 | I11: =AA11 -> 294324.5 | J11: =LN(I11/H11) -> 1.2460987 | K11: =J11-(aa-bb*H11) -> 0.16916396 | L11: 1957 | M11: 84630 | N11: 353281 | P11: =CE11 -> Grant | Q11: =CF11 -> 1957 | R11: =CN11 -> 84655 | S11: =CG11 -> 308363 | T11: =1-R11/S11 -> 0.72546966 | U11: =S11-R11 -> 223708 | W11: =$S14*W$2 -> 117214.2 | X11: =$S15*X$2 -> 152186.4 | Y11: =$S16*Y$2 -> 24923.9 | Z11: =$S17*Z$2 -> 0 | AA11: =SUM(W11:Z11) -> 294324.5 | AF11: =AA11 -> 294324.5 | AG11: =B11 -> 1957 | AH11: =W11/$AA11 -> 0.39824819 | AI11: =X11/$AA11 -> 0.5170701 | AJ11: =Y11/$AA11 -> 0.084681703 | AL11: =I11*AP11/H11*EXP(-bb*(AP11-H11)) -> 1361097.6 | AM11: =B11 -> 1957 | AN11: =AH8*AQ8+AI7*AQ7+AJ6*AQ6 -> 1016148.8 | AO11: =CHOOSE(umethod,T11,retroU,MAX(0,cslope*(AN11-nlim)/AN11)) -> 0.5 | AP11: =AN11*(1-AO11) -> 508074.38 | AQ11: =AP11*EXP(aa-bb*AP11+K11) -> 1361097.6 | AR11: =AN11-AP11 -> 508074.38 | AU11: 0.25 | AV11: 31449195 | AZ11: Cass | BA11: 1957 | BB11: 92528 | BC11: N/A | BD11: 123 | BE11: 0 | BF11: 48 | BG11: 124319 | BH11: 217018 | BI11: 0.72 | BJ11: 84630 | BK11: 301648 | BL11: =BH11/BK11 -> 0.7194412 | BM11: =BB11/BK11 -> 0.30674163 | BN11: =BD11/(BK11-BB11) -> 0.00058817904 | BO11: =BG11/(BK11-BB11-BD11-BF11) -> 0.59497294 | BP11: =BH11/BK11 -> 0.7194412 | BQ11: =BJ11*BP11/(1-BP11) -> 217018 | BS11: =BM11/(SUM($BM11:$BO11)) -> 0.33995423 | BT11: =BN11/(SUM($BM11:$BO11)) -> 0.0006518644 | BU11: =BO11/(SUM($BM11:$BO11)) -> 0.65939391 | CE11: Grant | CF11: 1957 | CG11: 308363 | CH11: 97399 | CI11: 600 | CJ11: 1444 | CK11: 0 | CL11: 0 | CM11: 124265 | CN11: 84655 | CO11: =SUM(CH11:CN11) -> 308363 | CQ11: 0.725 | CR11: =CF11 -> 1957 | CS11: =(CG11-BK11)/BK11 -> 0.022261046 | CT11: =(CN11-BJ11)/BJ11 -> 0.00029540352
A12: =P12 -> Grant | B12: =L12 -> 1958 | C12: =M12 -> 89375 | D12: =N12 -> 302174 | E12: =LN(D12/C12) -> 1.218162 | F12: =A12 -> Grant | G12: 20038.595 | H12: =R12 -> 89400 | I12: =AA12 -> 259625 | J12: =LN(I12/H12) -> 1.0661176 | K12: =J12-(aa-bb*H12) -> -0.0078958852 | L12: 1958 | M12: 89375 | N12: 302174 | P12: =CE12 -> Grant | Q12: =CF12 -> 1958 | R12: =CN12 -> 89400 | S12: =CG12 -> 559829 | T12: =1-R12/S12 -> 0.84030838 | U12: =S12-R12 -> 470429 | W12: =$S15*W$2 -> 76093.2 | X12: =$S16*X$2 -> 149543.4 | Y12: =$S17*Y$2 -> 33988.4 | Z12: =$S18*Z$2 -> 0 | AA12: =SUM(W12:Z12) -> 259625 | AF12: =AA12 -> 259625 | AG12: =B12 -> 1958 | AH12: =W12/$AA12 -> 0.29308888 | AI12: =X12/$AA12 -> 0.57599769 | AJ12: =Y12/$AA12 -> 0.13091343 | AL12: =I12*AP12/H12*EXP(-bb*(AP12-H12)) -> 1740855.3 | AM12: =B12 -> 1958 | AN12: =AH9*AQ9+AI8*AQ8+AJ7*AQ7 -> 2311598.2 | AO12: =CHOOSE(umethod,T12,retroU,MAX(0,cslope*(AN12-nlim)/AN12)) -> 0.5 | AP12: =AN12*(1-AO12) -> 1155799.1 | AQ12: =AP12*EXP(aa-bb*AP12+K12) -> 1740855.3 | AR12: =AN12-AP12 -> 1155799.1 | AU12: 0.3 | AV12: 37151337 | AZ12: Cass | BA12: 1958 | BB12: 252287 | BC12: N/A | BD12: 1178 | BE12: 0 | BF12: 690 | BG12: 202075 | BH12: 456230 | BI12: 0.84 | BJ12: 89375 | BK12: 545605 | BL12: =BH12/BK12 -> 0.83619102 | BM12: =BB12/BK12 -> 0.46239862 | BN12: =BD12/(BK12-BB12) -> 0.004016119 | BO12: =BG12/(BK12-BB12-BD12-BF12) -> 0.69334363 | BP12: =BH12/BK12 -> 0.83619102 | BQ12: =BJ12*BP12/(1-BP12) -> 456230 | BS12: =BM12/(SUM($BM12:$BO12)) -> 0.39870255 | BT12: =BN12/(SUM($BM12:$BO12)) -> 0.0034628929 | BU12: =BO12/(SUM($BM12:$BO12)) -> 0.59783455 | CE12: Grant | CF12: 1958 | CG12: 559829 | CH12: 247648 | CI12: 8879 | CJ12: 11935 | CK12: 0 | CL12: 0 | CM12: 201968 | CN12: 89400 | CO12: =SUM(CH12:CN12) -> 559830 | CQ12: 0.84 | CR12: =CF12 -> 1958 | CS12: =(CG12-BK12)/BK12 -> 0.026070142 | CT12: =(CN12-BJ12)/BJ12 -> 0.00027972028
A13: =P13 -> Grant | B13: =L13 -> 1959 | C13: =M13 -> 152300 | D13: =N13 -> 361837 | E13: =LN(D13/C13) -> 0.86534157 | F13: =A13 -> Grant | G13: 15904.252 | H13: =R13 -> 152300 | I13: =AA13 -> 315857.7 | J13: =LN(I13/H13) -> 0.72943954 | K13: =J13-(aa-bb*H13) -> -0.30584931 | L13: 1959 | M13: 152300 | N13: 361837 | P13: =CE13 -> Grant | Q13: =CF13 -> 1959 | R13: =CN13 -> 152300 | S13: =CG13 -> 651622 | T13: =1-R13/S13 -> 0.76627554 | U13: =S13-R13 -> 499322 | W13: =$S16*W$2 -> 74771.7 | X13: =$S17*X$2 -> 203930.4 | Y13: =$S18*Y$2 -> 37155.6 | Z13: =$S19*Z$2 -> 0 | AA13: =SUM(W13:Z13) -> 315857.7 | AF13: =AA13 -> 315857.7 | AG13: =B13 -> 1959 | AH13: =W13/$AA13 -> 0.23672591 | AI13: =X13/$AA13 -> 0.64564011 | AJ13: =Y13/$AA13 -> 0.11763399 | AL13: =I13*AP13/H13*EXP(-bb*(AP13-H13)) -> 1361035.9 | AM13: =B13 -> 1959 | AN13: =AH10*AQ10+AI9*AQ9+AJ8*AQ8 -> 3272736.9 | AO13: =CHOOSE(umethod,T13,retroU,MAX(0,cslope*(AN13-nlim)/AN13)) -> 0.5 | AP13: =AN13*(1-AO13) -> 1636368.4 | AQ13: =AP13*EXP(aa-bb*AP13+K13) -> 1361035.9 | AR13: =AN13-AP13 -> 1636368.4 | AU13: 0.35 | AV13: 42330917 | AZ13: Cass | BA13: 1959 | BB13: 218898 | BC13: N/A | BD13: 1448 | BE13: 0 | BF13: 996 | BG13: 237091 | BH13: 458433 | BI13: 0.75 | BJ13: 152300 | BK13: 610733 | BL13: =BH13/BK13 -> 0.75062752 | BM13: =BB13/BK13 -> 0.35841849 | BN13: =BD13/(BK13-BB13) -> 0.003695433 | BO13: =BG13/(BK13-BB13-BD13-BF13) -> 0.60887642 | BP13: =BH13/BK13 -> 0.75062752 | BQ13: =BJ13*BP13/(1-BP13) -> 458433 | BS13: =BM13/(SUM($BM13:$BO13)) -> 0.36912673 | BT13: =BN13/(SUM($BM13:$BO13)) -> 0.0038058391 | BU13: =BO13/(SUM($BM13:$BO13)) -> 0.62706743 | CE13: Grant | CF13: 1959 | CG13: 651622 | CH13: 241353 | CI13: 5430 | CJ13: 15632 | CK13: 0 | CL13: 0 | CM13: 236907 | CN13: 152300 | CO13: =SUM(CH13:CN13) -> 651622 | CQ13: 0.766 | CR13: =CF13 -> 1959 | CS13: =(CG13-BK13)/BK13 -> 0.066950697 | CT13: =(CN13-BJ13)/BJ13 -> 0
A14: =P14 -> Grant | B14: =L14 -> 1960 | C14: =M14 -> 263700 | D14: =N14 -> 416907 | E14: =LN(D14/C14) -> 0.45805108 | F14: =A14 -> Grant | G14: 13108.046 | H14: =R14 -> 144782 | I14: =AA14 -> 341946 | J14: =LN(I14/H14) -> 0.85942367 | K14: =J14-(aa-bb*H14) -> -0.18049366 | L14: 1960 | M14: 263700 | N14: 416907 | P14: =CE14 -> Grant | Q14: =CF14 -> 1960 | R14: =CN14 -> 144782 | S14: =CG14 -> 390714 | T14: =1-R14/S14 -> 0.62944251 | U14: =S14-R14 -> 245932 | W14: =$S17*W$2 -> 101965.2 | X14: =$S18*X$2 -> 222933.6 | Y14: =$S19*Y$2 -> 17047.2 | Z14: =$S20*Z$2 -> 0 | AA14: =SUM(W14:Z14) -> 341946 | AF14: =AA14 -> 341946 | AG14: =B14 -> 1960 | AH14: =W14/$AA14 -> 0.29819094 | AI14: =X14/$AA14 -> 0.65195557 | AJ14: =Y14/$AA14 -> 0.049853486 | AL14: =I14*AP14/H14*EXP(-bb*(AP14-H14)) -> 1515848.2 | AM14: =B14 -> 1960 | AN14: =AH11*AQ11+AI10*AQ10+AJ9*AQ9 -> 2675773.7 | AO14: =CHOOSE(umethod,T14,retroU,MAX(0,cslope*(AN14-nlim)/AN14)) -> 0.5 | AP14: =AN14*(1-AO14) -> 1337886.9 | AQ14: =AP14*EXP(aa-bb*AP14+K14) -> 1515848.2 | AR14: =AN14-AP14 -> 1337886.9 | AU14: 0.4 | AV14: 46719560 | AZ14: Cass | BA14: 1960 | BB14: 146889 | BC14: N/A | BD14: 4618 | BE14: 21523 | BF14: 185 | BG14: 77262 | BH14: 250476 | BI14: 0.49 | BJ14: 263700 | BK14: 514176 | BL14: =BH14/BK14 -> 0.48714059 | BM14: =BB14/BK14 -> 0.28567844 | BN14: =BD14/(BK14-BB14) -> 0.012573274 | BO14: =BG14/(BK14-BB14-BD14-BF14) -> 0.21314596 | BP14: =BH14/BK14 -> 0.48714059 | BQ14: =BJ14*BP14/(1-BP14) -> 250476 | BS14: =BM14/(SUM($BM14:$BO14)) -> 0.55862288 | BT14: =BN14/(SUM($BM14:$BO14)) -> 0.024586099 | BU14: =BO14/(SUM($BM14:$BO14)) -> 0.41679102 | CE14: Grant | CF14: 1960 | CG14: 390714 | CH14: 141635 | CI14: 1189 | CJ14: 4310 | CK14: 21523 | CL14: 185 | CM14: 77090 | CN14: 144782 | CO14: =SUM(CH14:CN14) -> 390714 | CQ14: 0.629 | CR14: =CF14 -> 1960 | CS14: =(CG14-BK14)/BK14 -> -0.24011622 | CT14: =(CN14-BJ14)/BJ14 -> -0.45095942
A15: =P15 -> Grant | B15: =L15 -> 1961 | C15: =M15 -> 172700 | D15: =N15 -> 288161 | E15: =LN(D15/C15) -> 0.51196337 | F15: =A15 -> Grant | G15: 12157.238 | H15: =R15 -> 103920 | I15: =AA15 -> 255725.9 | J15: =LN(I15/H15) -> 0.9004848 | K15: =J15-(aa-bb*H15) -> -0.16458939 | L15: 1961 | M15: 172700 | N15: 288161 | P15: =CE15 -> Grant | Q15: =CF15 -> 1961 | R15: =CN15 -> 103920 | S15: =CG15 -> 253644 | T15: =1-R15/S15 -> 0.59029191 | U15: =S15-R15 -> 149724 | W15: =$S18*W$2 -> 111466.8 | X15: =$S19*X$2 -> 102283.2 | Y15: =$S20*Y$2 -> 41975.9 | Z15: =$S21*Z$2 -> 0 | AA15: =SUM(W15:Z15) -> 255725.9 | AF15: =AA15 -> 255725.9 | AG15: =B15 -> 1961 | AH15: =W15/$AA15 -> 0.43588389 | AI15: =X15/$AA15 -> 0.399972 | AJ15: =Y15/$AA15 -> 0.16414411 | AM15: =B15 -> 1961 | AN15: =AH12*AQ12+AI11*AQ11+AJ10*AQ10 -> 1430925 | AO15: =CHOOSE(umethod,T15,retroU,MAX(0,cslope*(AN15-nlim)/AN15)) -> 0.5 | AP15: =AN15*(1-AO15) -> 715462.48 | AQ15: =AP15*EXP(aa-bb*AP15+K15) -> 1208234.3 | AR15: =AN15-AP15 -> 715462.48 | AU15: 0.45 | AV15: 49924457 | AZ15: Cass | BA15: 1961 | BB15: 65963 | BC15: N/A | BD15: 5894 | BE15: 15803 | BF15: 20 | BG15: 57545 | BH15: 145224 | BI15: 0.46 | BJ15: 172700 | BK15: 317924 | BL15: =BH15/BK15 -> 0.45678841 | BM15: =BB15/BK15 -> 0.2074804 | BN15: =BD15/(BK15-BB15) -> 0.023392509 | BO15: =BG15/(BK15-BB15-BD15-BF15) -> 0.23387808 | BP15: =BH15/BK15 -> 0.45678841 | BQ15: =BJ15*BP15/(1-BP15) -> 145224 | BS15: =BM15/(SUM($BM15:$BO15)) -> 0.44643348 | BT15: =BN15/(SUM($BM15:$BO15)) -> 0.050333425 | BU15: =BO15/(SUM($BM15:$BO15)) -> 0.50323309 | CE15: Grant | CF15: 1961 | CG15: 253644 | CH15: 69640 | CI15: 1131 | CJ15: 5676 | CK15: 15803 | CL15: 20 | CM15: 57454 | CN15: 103920 | CO15: =SUM(CH15:CN15) -> 253644 | CQ15: 0.59 | CR15: =CF15 -> 1961 | CS15: =(CG15-BK15)/BK15 -> -0.20218669 | CT15: =(CN15-BJ15)/BJ15 -> -0.39826288
A16: =P16 -> Grant | B16: =L16 -> 1962 | C16: =M16 -> 180200 | D16: =N16 -> 423280 | E16: =LN(D16/C16) -> 0.85396655 | F16: =A16 -> Grant | G16: 10463.341 | H16: =R16 -> 130357 | I16: =AA16 -> 335297.3 | J16: =LN(I16/H16) -> 0.94474076 | K16: =J16-(aa-bb*H16) -> -0.10405738 | L16: 1962 | M16: 180200 | N16: 423280 | P16: =CE16 -> Grant | Q16: =CF16 -> 1962 | R16: =CN16 -> 130357 | S16: =CG16 -> 249239 | T16: =1-R16/S16 -> 0.47697993 | U16: =S16-R16 -> 118882 | W16: =$S19*W$2 -> 51141.6 | X16: =$S20*X$2 -> 251855.4 | Y16: =$S21*Y$2 -> 32300.3 | Z16: =$S22*Z$2 -> 0 | AA16: =SUM(W16:Z16) -> 335297.3 | AF16: =AA16 -> 335297.3 | AG16: =B16 -> 1962 | AH16: =W16/$AA16 -> 0.15252613 | AI16: =X16/$AA16 -> 0.75114055 | AJ16: =Y16/$AA16 -> 0.096333314 | AM16: =B16 -> 1962 | AN16: =AH13*AQ13+AI12*AQ12+AJ11*AQ11 -> 1440181.2 | AO16: =CHOOSE(umethod,T16,retroU,MAX(0,cslope*(AN16-nlim)/AN16)) -> 0.5 | AP16: =AN16*(1-AO16) -> 720090.59 | AQ16: =AP16*EXP(aa-bb*AP16+K16) -> 1288257.6 | AR16: =AN16-AP16 -> 720090.59 | AU16: 0.5 | AV16: 51361535 | AZ16: Cass | BA16: 1962 | BB16: 36568 | BC16: N/A | BD16: 8034 | BE16: 8741 | BF16: 33 | BG16: 58870 | BH16: 112245 | BI16: 0.38 | BJ16: 180200 | BK16: 292445 | BL16: =BH16/BK16 -> 0.38381576 | BM16: =BB16/BK16 -> 0.12504232 | BN16: =BD16/(BK16-BB16) -> 0.031397898 | BO16: =BG16/(BK16-BB16-BD16-BF16) -> 0.23756103 | BP16: =BH16/BK16 -> 0.38381576 | BQ16: =BJ16*BP16/(1-BP16) -> 112245 | BS16: =BM16/(SUM($BM16:$BO16)) -> 0.31736528 | BT16: =BN16/(SUM($BM16:$BO16)) -> 0.079689844 | BU16: =BO16/(SUM($BM16:$BO16)) -> 0.60294488 | CE16: Grant | CF16: 1962 | CG16: 249239 | CH16: 42750 | CI16: 1338 | CJ16: 7155 | CK16: 8741 | CL16: 33 | CM16: 58866 | CN16: 130357 | CO16: =SUM(CH16:CN16) -> 249240 | CQ16: 0.477 | CR16: =CF16 -> 1962 | CS16: =(CG16-BK16)/BK16 -> -0.1477406 | CT16: =(CN16-BJ16)/BJ16 -> -0.27659822
A17: =P17 -> Grant | B17: =L17 -> 1963 | C17: =M17 -> 214200 | D17: =N17 -> 430785 | E17: =LN(D17/C17) -> 0.69869897 | F17: =A17 -> Grant | G17: 9070.6091 | H17: =R17 -> 192245 | I17: =AA17 -> 435055.2 | J17: =LN(I17/H17) -> 0.81670232 | K17: =J17-(aa-bb*H17) -> -0.19399422 | L17: 1963 | M17: 214200 | N17: 430785 | P17: =CE17 -> Grant | Q17: =CF17 -> 1963 | R17: =CN17 -> 192245 | S17: =CG17 -> 339884 | T17: =1-R17/S17 -> 0.43438055 | U17: =S17-R17 -> 147639 | W17: =$S20*W$2 -> 125927.7 | X17: =$S21*X$2 -> 193801.8 | Y17: =$S22*Y$2 -> 115325.7 | Z17: =$S23*Z$2 -> 0 | AA17: =SUM(W17:Z17) -> 435055.2 | AF17: =AA17 -> 435055.2 | AG17: =B17 -> 1963 | AH17: =W17/$AA17 -> 0.28945224 | AI17: =X17/$AA17 -> 0.44546485 | AJ17: =Y17/$AA17 -> 0.26508291 | AM17: =B17 -> 1963 | AN17: =AH14*AQ14+AI13*AQ13+AJ12*AQ12 -> 1558652.9 | AO17: =CHOOSE(umethod,T17,retroU,MAX(0,cslope*(AN17-nlim)/AN17)) -> 0.5 | AP17: =AN17*(1-AO17) -> 779326.46 | AQ17: =AP17*EXP(aa-bb*AP17+K17) -> 1228677 | AR17: =AN17-AP17 -> 779326.46 | AU17: 0.55 | AV17: 50157606 | AZ17: Cass | BA17: 1963 | BB17: 75293 | BC17: N/A | BD17: 9163 | BE17: 9807 | BF17: 360 | BG17: 64548 | BH17: 159172 | BI17: 0.43 | BJ17: 214200 | BK17: 373372 | BL17: =BH17/BK17 -> 0.42630942 | BM17: =BB17/BK17 -> 0.20165679 | BN17: =BD17/(BK17-BB17) -> 0.030740173 | BO17: =BG17/(BK17-BB17-BD17-BF17) -> 0.22369315 | BP17: =BH17/BK17 -> 0.42630942 | BQ17: =BJ17*BP17/(1-BP17) -> 159172 | BS17: =BM17/(SUM($BM17:$BO17)) -> 0.44214243 | BT17: =BN17/(SUM($BM17:$BO17)) -> 0.067399341 | BU17: =BO17/(SUM($BM17:$BO17)) -> 0.49045823 | CE17: Grant | CF17: 1963 | CG17: 339884 | CH17: 65476 | CI17: 0 | CJ17: 7567 | CK17: 9807 | CL17: 360 | CM17: 64428 | CN17: 192245 | CO17: =SUM(CH17:CN17) -> 339883 | CQ17: 0.434 | CR17: =CF17 -> 1963 | CS17: =(CG17-BK17)/BK17 -> -0.089690711 | CT17: =(CN17-BJ17)/BJ17 -> -0.10249767
A18: =P18 -> Grant | B18: =L18 -> 1964 | C18: =M18 -> 325400 | D18: =N18 -> 1165723 | E18: =LN(D18/C18) -> 1.2760416 | F18: =A18 -> Grant | G18: 7710.0916 | H18: =R18 -> 246741 | I18: =AA18 -> 846704.4 | J18: =LN(I18/H18) -> 1.2330124 | K18: =J18-(aa-bb*H18) -> 0.25586658 | L18: 1964 | M18: 325400 | N18: 1165723 | P18: =CE18 -> Grant | Q18: =CF18 -> 1964 | R18: =CN18 -> 246741 | S18: =CG18 -> 371556 | T18: =1-R18/S18 -> 0.33592514 | U18: =S18-R18 -> 124815 | W18: =$S21*W$2 -> 96900.9 | X18: =$S22*X$2 -> 691954.2 | Y18: =$S23*Y$2 -> 57849.3 | Z18: =$S24*Z$2 -> 0 | AA18: =SUM(W18:Z18) -> 846704.4 | AF18: =AA18 -> 846704.4 | AG18: =B18 -> 1964 | AH18: =W18/$AA18 -> 0.11444478 | AI18: =X18/$AA18 -> 0.81723232 | AJ18: =Y18/$AA18 -> 0.0683229 | AM18: =B18 -> 1964 | AN18: =AH15*AQ15+AI14*AQ14+AJ13*AQ13 -> 1675019.6 | AO18: =CHOOSE(umethod,T18,retroU,MAX(0,cslope*(AN18-nlim)/AN18)) -> 0.5 | AP18: =AN18*(1-AO18) -> 837509.81 | AQ18: =AP18*EXP(aa-bb*AP18+K18) -> 1997668.8 | AR18: =AN18-AP18 -> 837509.81 | AU18: 0.6 | AV18: 45080596 | AZ18: Cass | BA18: 1964 | BB18: 27470 | BC18: N/A | BD18: 9025 | BE18: 11350 | BF18: 437 | BG18: 73031 | BH18: 121313 | BI18: 0.27 | BJ18: 325400 | BK18: 446713 | BL18: =BH18/BK18 -> 0.2715681 | BM18: =BB18/BK18 -> 0.061493621 | BN18: =BD18/(BK18-BB18) -> 0.021526895 | BO18: =BG18/(BK18-BB18-BD18-BF18) -> 0.17821959 | BP18: =BH18/BK18 -> 0.2715681 | BQ18: =BJ18*BP18/(1-BP18) -> 121313 | BS18: =BM18/(SUM($BM18:$BO18)) -> 0.2353912 | BT18: =BN18/(SUM($BM18:$BO18)) -> 0.08240272 | BU18: =BO18/(SUM($BM18:$BO18)) -> 0.68220608 | CE18: Grant | CF18: 1964 | CG18: 371556 | CH18: 31979 | CI18: 0 | CJ18: 8372 | CK18: 11350 | CL18: 437 | CM18: 72677 | CN18: 246741 | CO18: =SUM(CH18:CN18) -> 371556 | CQ18: 0.336 | CR18: =CF18 -> 1964 | CS18: =(CG18-BK18)/BK18 -> -0.16824449 | CT18: =(CN18-BJ18)/BJ18 -> -0.24173018
A19: =P19 -> Grant | B19: =L19 -> 1965 | C19: =M19 -> 184800 | D19: =N19 -> 851349 | E19: =LN(D19/C19) -> 1.527548 | F19: =A19 -> Grant | G19: 7002.9849 | H19: =R19 -> 129459 | I19: =AA19 -> 767008.4 | J19: =LN(I19/H19) -> 1.7791335 | K19: =J19-(aa-bb*H19) -> 0.72978253 | L19: 1965 | M19: 184800 | N19: 851349 | P19: =CE19 -> Grant | Q19: =CF19 -> 1965 | R19: =CN19 -> 129459 | S19: =CG19 -> 170472 | T19: =1-R19/S19 -> 0.24058496 | U19: =S19-R19 -> 41013 | W19: =$S22*W$2 -> 345977.1 | X19: =$S23*X$2 -> 347095.8 | Y19: =$S24*Y$2 -> 73935.5 | Z19: =$S25*Z$2 -> 0 | AA19: =SUM(W19:Z19) -> 767008.4 | AF19: =AA19 -> 767008.4 | AG19: =B19 -> 1965 | AH19: =W19/$AA19 -> 0.45107342 | AI19: =X19/$AA19 -> 0.45253194 | AJ19: =Y19/$AA19 -> 0.096394642 | AM19: =B19 -> 1965 | AN19: =AH16*AQ16+AI15*AQ15+AJ14*AQ14 -> 755323.15 | AO19: =CHOOSE(umethod,T19,retroU,MAX(0,cslope*(AN19-nlim)/AN19)) -> 0.5 | AP19: =AN19*(1-AO19) -> 377661.57 | AQ19: =AP19*EXP(aa-bb*AP19+K19) -> 1920469.7 | AR19: =AN19-AP19 -> 377661.57 | AU19: 0.65 | AV19: 35049888 | AZ19: Cass | BA19: 1965 | BB19: 4270 | BC19: N/A | BD19: 8713 | BE19: 5595 | BF19: 203 | BG19: 19329 | BH19: 38110 | BI19: 0.17 | BJ19: 184800 | BK19: 222910 | BL19: =BH19/BK19 -> 0.17096586 | BM19: =BB19/BK19 -> 0.019155713 | BN19: =BD19/(BK19-BB19) -> 0.039850896 | BO19: =BG19/(BK19-BB19-BD19-BF19) -> 0.092163987 | BP19: =BH19/BK19 -> 0.17096586 | BQ19: =BJ19*BP19/(1-BP19) -> 38110 | BS19: =BM19/(SUM($BM19:$BO19)) -> 0.12671587 | BT19: =BN19/(SUM($BM19:$BO19)) -> 0.26361539 | BU19: =BO19/(SUM($BM19:$BO19)) -> 0.60966874 | CE19: Grant | CF19: 1965 | CG19: 170472 | CH19: 8447 | CI19: 0 | CJ19: 7566 | CK19: 5595 | CL19: 203 | CM19: 19202 | CN19: 129459 | CO19: =SUM(CH19:CN19) -> 170472 | CQ19: 0.241 | CR19: =CF19 -> 1965 | CS19: =(CG19-BK19)/BK19 -> -0.23524292 | CT19: =(CN19-BJ19)/BJ19 -> -0.29946429
A20: =P20 -> Grant | B20: =L20 -> 1966 | C20: =M20 -> 429700 | D20: =N20 -> 719419 | E20: =LN(D20/C20) -> 0.51535665 | F20: =A20 -> Grant | G20: 6693.7966 | H20: =R20 -> 360810 | I20: =AA20 -> 654797.3 | J20: =LN(I20/H20) -> 0.59597422 | K20: =J20-(aa-bb*H20) -> -0.31094458 | L20: 1966 | M20: 429700 | N20: 719419 | P20: =CE20 -> Grant | Q20: =CF20 -> 1966 | R20: =CN20 -> 360810 | S20: =CG20 -> 419759 | T20: =1-R20/S20 -> 0.14043535 | U20: =S20-R20 -> 58949 | W20: =$S23*W$2 -> 173547.9 | X20: =$S24*X$2 -> 443613 | Y20: =$S25*Y$2 -> 37636.4 | Z20: =$S26*Z$2 -> 0 | AA20: =SUM(W20:Z20) -> 654797.3 | AF20: =AA20 -> 654797.3 | AG20: =B20 -> 1966 | AH20: =W20/$AA20 -> 0.26504065 | AI20: =X20/$AA20 -> 0.67748141 | AJ20: =Y20/$AA20 -> 0.05747794 | AM20: =B20 -> 1966 | AN20: =AH17*AQ17+AI16*AQ16+AJ15*AQ15 -> 1521630.3 | AO20: =CHOOSE(umethod,T20,retroU,MAX(0,cslope*(AN20-nlim)/AN20)) -> 0.5 | AP20: =AN20*(1-AO20) -> 760815.17 | AQ20: =AP20*EXP(aa-bb*AP20+K20) -> 1079334.4 | AR20: =AN20-AP20 -> 760815.17 | AU20: 0.7 | AV20: 22241593 | AZ20: Cass | BA20: 1966 | BB20: 8860 | BC20: N/A | BD20: 8219 | BE20: 10083 | BF20: 216 | BG20: 26054 | BH20: 53432 | BI20: 0.11 | BJ20: 429700 | BK20: 483132 | BL20: =BH20/BK20 -> 0.11059503 | BM20: =BB20/BK20 -> 0.018338673 | BN20: =BD20/(BK20-BB20) -> 0.017329718 | BO20: =BG20/(BK20-BB20-BD20-BF20) -> 0.055929435 | BP20: =BH20/BK20 -> 0.11059503 | BQ20: =BJ20*BP20/(1-BP20) -> 53432 | BS20: =BM20/(SUM($BM20:$BO20)) -> 0.20020861 | BT20: =BN20/(SUM($BM20:$BO20)) -> 0.18919355 | BU20: =BO20/(SUM($BM20:$BO20)) -> 0.61059784 | CE20: Grant | CF20: 1966 | CG20: 419759 | CH20: 15213 | CI20: 0 | CJ20: 7402 | CK20: 10083 | CL20: 216 | CM20: 26035 | CN20: 360810 | CO20: =SUM(CH20:CN20) -> 419759 | CQ20: 0.14 | CR20: =CF20 -> 1966 | CS20: =(CG20-BK20)/BK20 -> -0.13117119 | CT20: =(CN20-BJ20)/BJ20 -> -0.16032115
A21: =P21 -> Grant | B21: =L21 -> 1967 | C21: =M21 -> 213873 | D21: =N21 -> 526762 | E21: =LN(D21/C21) -> 0.90136645 | F21: =A21 -> Grant | G21: 6634.8212 | H21: =R21 -> 213873 | I21: =AA21 -> 582606.9 | J21: =LN(I21/H21) -> 1.0021303 | K21: =J21-(aa-bb*H21) -> 0.0047491372 | L21: 1967 | M21: 213873 | N21: 526762 | P21: =CE21 -> Grant | Q21: =CF21 -> 1967 | R21: =CN21 -> 213873 | S21: =CG21 -> 323003 | T21: =1-R21/S21 -> 0.33786064 | U21: =S21-R21 -> 109130 | W21: =$S24*W$2 -> 221806.5 | X21: =$S25*X$2 -> 225818.4 | Y21: =$S26*Y$2 -> 134982 | Z21: =$S27*Z$2 -> 0 | AA21: =SUM(W21:Z21) -> 582606.9 | AF21: =AA21 -> 582606.9 | AG21: =B21 -> 1967 | AH21: =W21/$AA21 -> 0.38071382 | AI21: =X21/$AA21 -> 0.38759994 | AJ21: =Y21/$AA21 -> 0.23168624 | AM21: =B21 -> 1967 | AN21: =AH18*AQ18+AI17*AQ17+AJ16*AQ16 -> 900057.29 | AO21: =CHOOSE(umethod,T21,retroU,MAX(0,cslope*(AN21-nlim)/AN21)) -> 0.5 | AP21: =AN21*(1-AO21) -> 450028.64 | AQ21: =AP21*EXP(aa-bb*AP21+K21) -> 1060028.8 | AR21: =AN21-AP21 -> 450028.64 | AU21: 0.75 | AV21: 13351959 | AZ21: Cass | BA21: 1967 | BB21: 36432 | BC21: N/A | BD21: 11948 | BE21: 9206 | BF21: 688 | BG21: 55457 | BH21: 113731 | BI21: 0.35 | BJ21: 213873 | BK21: 327604 | BL21: =BH21/BK21 -> 0.34715999 | BM21: =BB21/BK21 -> 0.11120743 | BN21: =BD21/(BK21-BB21) -> 0.041034165 | BO21: =BG21/(BK21-BB21-BD21-BF21) -> 0.19910173 | BP21: =BH21/BK21 -> 0.34715999 | BQ21: =BJ21*BP21/(1-BP21) -> 113731 | BS21: =BM21/(SUM($BM21:$BO21)) -> 0.31652069 | BT21: =BN21/(SUM($BM21:$BO21)) -> 0.11679221 | BU21: =BO21/(SUM($BM21:$BO21)) -> 0.5666871 | CE21: Grant | CF21: 1967 | CG21: 323003 | CH21: 35962 | CI21: 0 | CJ21: 7824 | CK21: 9206 | CL21: 688 | CM21: 55450 | CN21: 213873 | CO21: =SUM(CH21:CN21) -> 323003 | CQ21: 0.338 | CR21: =CF21 -> 1967 | CS21: =(CG21-BK21)/BK21 -> -0.014044395 | CT21: =(CN21-BJ21)/BJ21 -> 0
A22: =P22 -> Grant | B22: =L22 -> 1968 | C22: =M22 -> 822200 | D22: =N22 -> 1219850 | E22: =LN(D22/C22) -> 0.3944995 | F22: =A22 -> Grant | G22: 6677.8906 | H22: =R22 -> 670328 | I22: =AA22 -> 1073497.2 | J22: =LN(I22/H22) -> 0.47090986 | K22: =J22-(aa-bb*H22) -> -0.2454529 | L22: 1968 | M22: 822200 | N22: 1219850 | P22: =CE22 -> Grant | Q22: =CF22 -> 1968 | R22: =CN22 -> 670328 | S22: =CG22 -> 1153257 | T22: =1-R22/S22 -> 0.41875228 | U22: =S22-R22 -> 482929 | W22: =$S25*W$2 -> 112909.2 | X22: =$S26*X$2 -> 809892 | Y22: =$S27*Y$2 -> 150696 | Z22: =$S28*Z$2 -> 0 | AA22: =SUM(W22:Z22) -> 1073497.2 | AF22: =AA22 -> 1073497.2 | AG22: =B22 -> 1968 | AH22: =W22/$AA22 -> 0.10517885 | AI22: =X22/$AA22 -> 0.75444258 | AJ22: =Y22/$AA22 -> 0.14037857 | AM22: =B22 -> 1968 | AN22: =AH19*AQ19+AI18*AQ18+AJ17*AQ17 -> 2824533.6 | AO22: =CHOOSE(umethod,T22,retroU,MAX(0,cslope*(AN22-nlim)/AN22)) -> 0.5 | AP22: =AN22*(1-AO22) -> 1412266.8 | AQ22: =AP22*EXP(aa-bb*AP22+K22) -> 1432366.9 | AR22: =AN22-AP22 -> 1412266.8 | AZ22: Cass | BA22: 1968 | BB22: 298253 | BC22: N/A | BD22: 12960 | BE22: 77467 | BF22: 863 | BG22: 214264 | BH22: 603807 | BI22: 0.42 | BJ22: 822200 | BK22: 1426007 | BL22: =BH22/BK22 -> 0.42342499 | BM22: =BB22/BK22 -> 0.20915255 | BN22: =BD22/(BK22-BB22) -> 0.011491868 | BO22: =BG22/(BK22-BB22-BD22-BF22) -> 0.19234944 | BP22: =BH22/BK22 -> 0.42342499 | BQ22: =BJ22*BP22/(1-BP22) -> 603807 | BS22: =BM22/(SUM($BM22:$BO22)) -> 0.50643017 | BT22: =BN22/(SUM($BM22:$BO22)) -> 0.02782576 | BU22: =BO22/(SUM($BM22:$BO22)) -> 0.46574406 | CE22: Grant | CF22: 1968 | CG22: 1153257 | CH22: 179004 | CI22: 0 | CJ22: 11578 | CK22: 77467 | CL22: 863 | CM22: 214017 | CN22: 670328 | CO22: =SUM(CH22:CN22) -> 1153257 | CQ22: 0.419 | CR22: =CF22 -> 1968 | CS22: =(CG22-BK22)/BK22 -> -0.19126835 | CT22: =(CN22-BJ22)/BJ22 -> -0.18471418
A23: =P23 -> Grant | B23: =L23 -> 1969 | C23: =M23 -> 390100 | D23: =N23 -> 1312868 | E23: =LN(D23/C23) -> 1.2135662 | F23: =A23 -> Grant | G23: 6755.3387 | H23: =R23 -> 309220 | I23: =AA23 -> 1380907.4 | J23: =LN(I23/H23) -> 1.4964431 | K23: =J23-(aa-bb*H23) -> 0.5577627 | L23: 1969 | M23: 390100 | N23: 1312868 | P23: =CE23 -> Grant | Q23: =CF23 -> 1969 | R23: =CN23 -> 309220 | S23: =CG23 -> 578493 | T23: =1-R23/S23 -> 0.46547322 | U23: =S23-R23 -> 269273 | W23: =$S26*W$2 -> 404946 | X23: =$S27*X$2 -> 904176 | Y23: =$S28*Y$2 -> 71785.4 | Z23: =$S29*Z$2 -> 0 | AA23: =SUM(W23:Z23) -> 1380907.4 | AF23: =AA23 -> 1380907.4 | AG23: =B23 -> 1969 | AH23: =W23/$AA23 -> 0.29324631 | AI23: =X23/$AA23 -> 0.65476947 | AJ23: =Y23/$AA23 -> 0.051984224 | AM23: =B23 -> 1969 | AN23: =AH20*AQ20+AI19*AQ19+AJ18*AQ18 -> 1291627.9 | AO23: =CHOOSE(umethod,T23,retroU,MAX(0,cslope*(AN23-nlim)/AN23)) -> 0.5 | AP23: =AN23*(1-AO23) -> 645813.95 | AQ23: =AP23*EXP(aa-bb*AP23+K23) -> 2344269.5 | AR23: =AN23-AP23 -> 645813.95 | AZ23: Cass | BA23: 1969 | BB23: 183798 | BC23: N/A | BD23: 6816 | BE23: 39026 | BF23: 735 | BG23: 93245 | BH23: 323620 | BI23: 0.45 | BJ23: 390100 | BK23: 713720 | BL23: =BH23/BK23 -> 0.45342711 | BM23: =BB23/BK23 -> 0.25752116 | BN23: =BD23/(BK23-BB23) -> 0.01286227 | BO23: =BG23/(BK23-BB23-BD23-BF23) -> 0.1785034 | BP23: =BH23/BK23 -> 0.45342711 | BQ23: =BJ23*BP23/(1-BP23) -> 323620 | BS23: =BM23/(SUM($BM23:$BO23)) -> 0.57368838 | BT23: =BN23/(SUM($BM23:$BO23)) -> 0.028653704 | BU23: =BO23/(SUM($BM23:$BO23)) -> 0.39765792 | CE23: Grant | CF23: 1969 | CG23: 578493 | CH23: 129729 | CI23: 0 | CJ23: 6331 | CK23: 39026 | CL23: 735 | CM23: 93453 | CN23: 309220 | CO23: =SUM(CH23:CN23) -> 578494 | CQ23: 0.465 | CR23: =CF23 -> 1969 | CS23: =(CG23-BK23)/BK23 -> -0.18946786 | CT23: =(CN23-BJ23)/BJ23 -> -0.20733145
A24: =P24 -> Grant | B24: =L24 -> 1970 | C24: =M24 -> 287250 | D24: =N24 -> 832641 | E24: =LN(D24/C24) -> 1.0642497 | F24: =A24 -> Grant | G24: 6841.2164 | H24: =R24 -> 284250 | I24: =AA24 -> 931420.3 | J24: =LN(I24/H24) -> 1.1868565 | K24: =J24-(aa-bb*H24) -> 0.23280321 | L24: 1970 | M24: 287250 | N24: 832641 | P24: =CE24 -> Grant | Q24: =CF24 -> 1970 | R24: =CN24 -> 284250 | S24: =CG24 -> 739355 | T24: =1-R24/S24 -> 0.61554328 | U24: =S24-R24 -> 455105 | W24: =$S27*W$2 -> 452088 | X24: =$S28*X$2 -> 430712.4 | Y24: =$S29*Y$2 -> 48619.9 | Z24: =$S30*Z$2 -> 0 | AA24: =SUM(W24:Z24) -> 931420.3 | AF24: =AA24 -> 931420.3 | AG24: =B24 -> 1970 | AH24: =W24/$AA24 -> 0.48537486 | AI24: =X24/$AA24 -> 0.46242539 | AJ24: =Y24/$AA24 -> 0.052199743 | AM24: =B24 -> 1970 | AN24: =AH21*AQ21+AI20*AQ20+AJ19*AQ19 -> 1319919.6 | AO24: =CHOOSE(umethod,T24,retroU,MAX(0,cslope*(AN24-nlim)/AN24)) -> 0.5 | AP24: =AN24*(1-AO24) -> 659959.8 | AQ24: =AP24*EXP(aa-bb*AP24+K24) -> 1715960.3 | AR24: =AN24-AP24 -> 659959.8 | AZ24: Cass | BA24: 1970 | BB24: 209072 | BC24: N/A | BD24: 11867 | BE24: 61134 | BF24: 332 | BG24: 184381 | BH24: 468787 | BI24: 0.62 | BJ24: 287250 | BK24: 754037 | BL24: =BH24/BK24 -> 0.62170291 | BM24: =BB24/BK24 -> 0.27727021 | BN24: =BD24/(BK24-BB24) -> 0.02177571 | BO24: =BG24/(BK24-BB24-BD24-BF24) -> 0.34608252 | BP24: =BH24/BK24 -> 0.62170291 | BQ24: =BJ24*BP24/(1-BP24) -> 472073.85 | BS24: =BM24/(SUM($BM24:$BO24)) -> 0.42979071 | BT24: =BN24/(SUM($BM24:$BO24)) -> 0.03375407 | BU24: =BO24/(SUM($BM24:$BO24)) -> 0.53645522 | CE24: Grant | CF24: 1970 | CG24: 739355 | CH24: 197753 | CI24: 675 | CJ24: 10345 | CK24: 61134 | CL24: 0 | CM24: 185198 | CN24: 284250 | CO24: =SUM(CH24:CN24) -> 739355 | CQ24: 0.616 | CR24: =CF24 -> 1970 | CS24: =(CG24-BK24)/BK24 -> -0.019471193 | CT24: =(CN24-BJ24)/BJ24 -> -0.010443864
A25: =P25 -> Grant | B25: =L25 -> 1971 | C25: =M25 -> 290150 | D25: =N25 -> 589068 | E25: =LN(D25/C25) -> 0.7081436 | F25: =A25 -> Grant | G25: 6933.9203 | H25: =R25 -> 290125 | I25: =AA25 -> 607447.8 | J25: =LN(I25/H25) -> 0.73895438 | K25: =J25-(aa-bb*H25) -> -0.21148193 | L25: 1971 | M25: 290150 | N25: 589068 | P25: =CE25 -> Grant | Q25: =CF25 -> 1971 | R25: =CN25 -> 290125 | S25: =CG25 -> 376364 | T25: =1-R25/S25 -> 0.22913722 | U25: =S25-R25 -> 86239 | W25: =$S28*W$2 -> 215356.2 | X25: =$S29*X$2 -> 291719.4 | Y25: =$S30*Y$2 -> 100372.2 | Z25: =$S31*Z$2 -> 0 | AA25: =SUM(W25:Z25) -> 607447.8 | AF25: =AA25 -> 607447.8 | AG25: =B25 -> 1971 | AH25: =W25/$AA25 -> 0.35452627 | AI25: =X25/$AA25 -> 0.48023781 | AJ25: =Y25/$AA25 -> 0.16523593 | AM25: =B25 -> 1971 | AN25: =AH22*AQ22+AI21*AQ21+AJ20*AQ20 -> 623559.72 | AO25: =CHOOSE(umethod,T25,retroU,MAX(0,cslope*(AN25-nlim)/AN25)) -> 0.5 | AP25: =AN25*(1-AO25) -> 311779.86 | AQ25: =AP25*EXP(aa-bb*AP25+K25) -> 644142.41 | AR25: =AN25-AP25 -> 311779.86 | AZ25: Cass | BA25: 1971 | BB25: 40206 | BC25: N/A | BD25: 9162 | BE25: 19848 | BF25: 193 | BG25: 25716 | BH25: 95125 | BI25: 0.25 | BJ25: 290150 | BK25: 385275 | BL25: =BH25/BK25 -> 0.24690156 | BM25: =BB25/BK25 -> 0.10435663 | BN25: =BD25/(BK25-BB25) -> 0.026551211 | BO25: =BG25/(BK25-BB25-BD25-BF25) -> 0.076600916 | BP25: =BH25/BK25 -> 0.24690156 | BQ25: =BJ25*BP25/(1-BP25) -> 95125 | BS25: =BM25/(SUM($BM25:$BO25)) -> 0.50290229 | BT25: =BN25/(SUM($BM25:$BO25)) -> 0.12795225 | BU25: =BO25/(SUM($BM25:$BO25)) -> 0.36914546 | CE25: Grant | CF25: 1971 | CG25: 376364 | CH25: 33093 | CI25: 0 | CJ25: 7502 | CK25: 19850 | CL25: 0 | CM25: 25794 | CN25: 290125 | CO25: =SUM(CH25:CN25) -> 376364 | CQ25: 0.229 | CR25: =CF25 -> 1971 | CS25: =(CG25-BK25)/BK25 -> -0.023128934 | CT25: =(CN25-BJ25)/BJ25 -> -8.616233e-05
A26: =P26 -> Grant | B26: =L26 -> 1972 | C26: =M26 -> 423290 | D26: =N26 -> 965520 | E26: =LN(D26/C26) -> 0.82460929 | F26: =A26 -> Grant | G26: 7033.993 | H26: =R26 -> 423290 | I26: =AA26 -> 820346.5 | J26: =LN(I26/H26) -> 0.66166929 | K26: =J26-(aa-bb*H26) -> -0.20678344 | L26: 1972 | M26: 423290 | N26: 965520 | P26: =CE26 -> Grant | Q26: =CF26 -> 1972 | R26: =CN26 -> 423290 | S26: =CG26 -> 1349820 | T26: =1-R26/S26 -> 0.68641004 | U26: =S26-R26 -> 926530 | W26: =$S29*W$2 -> 145859.7 | X26: =$S30*X$2 -> 602233.2 | Y26: =$S31*Y$2 -> 72253.6 | Z26: =$S32*Z$2 -> 0 | AA26: =SUM(W26:Z26) -> 820346.5 | AF26: =AA26 -> 820346.5 | AG26: =B26 -> 1972 | AH26: =W26/$AA26 -> 0.17780255 | AI26: =X26/$AA26 -> 0.73412052 | AJ26: =Y26/$AA26 -> 0.088076928 | AM26: =B26 -> 1972 | AN26: =AH23*AQ23+AI22*AQ22+AJ21*AQ21 -> 2013681 | AO26: =CHOOSE(umethod,T26,retroU,MAX(0,cslope*(AN26-nlim)/AN26)) -> 0.5 | AP26: =AN26*(1-AO26) -> 1006840.5 | AQ26: =AP26*EXP(aa-bb*AP26+K26) -> 1362363.7 | AR26: =AN26-AP26 -> 1006840.5 | AZ26: Cass | BA26: 1972 | BB26: 444705 | BC26: N/A | BD26: 40334 | BE26: 252043 | BF26: 600 | BG26: 262836 | BH26: 1000517 | BI26: 0.7 | BJ26: 423290 | BK26: 1423807 | BL26: =BH26/BK26 -> 0.70270549 | BM26: =BB26/BK26 -> 0.31233517 | BN26: =BD26/(BK26-BB26) -> 0.041194891 | BO26: =BG26/(BK26-BB26-BD26-BF26) -> 0.28015878 | BP26: =BH26/BK26 -> 0.70270549 | BQ26: =BJ26*BP26/(1-BP26) -> 1000517 | BS26: =BM26/(SUM($BM26:$BO26)) -> 0.49288413 | BT26: =BN26/(SUM($BM26:$BO26)) -> 0.065008074 | BU26: =BO26/(SUM($BM26:$BO26)) -> 0.4421078 | CE26: Grant | CF26: 1972 | CG26: 1349820 | CH26: 358496 | CI26: 15952 | CJ26: 37276 | CK26: 252043 | CL26: 0 | CM26: 262763 | CN26: 423290 | CO26: =SUM(CH26:CN26) -> 1349820 | CQ26: 0.686 | CR26: =CF26 -> 1972 | CS26: =(CG26-BK26)/BK26 -> -0.051964206 | CT26: =(CN26-BJ26)/BJ26 -> 0
A27: =P27 -> Grant | B27: =L27 -> 1973 | C27: =M27 -> 267105 | D27: =N27 -> 826929 | E27: =LN(D27/C27) -> 1.130077 | F27: =A27 -> Grant | G27: 7142.0201 | H27: =R27 -> 267080 | I27: =AA27 -> 853160.5 | J27: =LN(I27/H27) -> 1.1613995 | K27: =J27-(aa-bb*H27) -> 0.19677539 | L27: 1973 | M27: 267105 | N27: 826929 | P27: =CE27 -> Grant | Q27: =CF27 -> 1973 | R27: =CN27 -> 267080 | S27: =CG27 -> 1506960 | T27: =1-R27/S27 -> 0.82276902 | U27: =S27-R27 -> 1239880 | W27: =$S30*W$2 -> 301116.6 | X27: =$S31*X$2 -> 433521.6 | Y27: =$S32*Y$2 -> 118522.3 | Z27: =$S33*Z$2 -> 0 | AA27: =SUM(W27:Z27) -> 853160.5 | AF27: =AA27 -> 853160.5 | AG27: =B27 -> 1973 | AH27: =W27/$AA27 -> 0.3529425 | AI27: =X27/$AA27 -> 0.50813604 | AJ27: =Y27/$AA27 -> 0.13892146 | AM27: =B27 -> 1973 | AN27: =AH24*AQ24+AI23*AQ23+AJ22*AQ22 -> 2568913.7 | AO27: =CHOOSE(umethod,T27,retroU,MAX(0,cslope*(AN27-nlim)/AN27)) -> 0.5 | AP27: =AN27*(1-AO27) -> 1284456.8 | AQ27: =AP27*EXP(aa-bb*AP27+K27) -> 2193247.1 | AR27: =AN27-AP27 -> 1284456.8 | AZ27: Cass | BA27: 1973 | BB27: 590246 | BC27: N/A | BD27: 80727 | BE27: 200744 | BF27: 643 | BG27: 201278 | BH27: 1073638 | BI27: 0.8 | BJ27: 267105 | BK27: 1340743 | BL27: =BH27/BK27 -> 0.80077837 | BM27: =BB27/BK27 -> 0.44023799 | BN27: =BD27/(BK27-BB27) -> 0.10756472 | BO27: =BG27/(BK27-BB27-BD27-BF27) -> 0.30080687 | BP27: =BH27/BK27 -> 0.80077837 | BQ27: =BJ27*BP27/(1-BP27) -> 1073638 | BS27: =BM27/(SUM($BM27:$BO27)) -> 0.51877565 | BT27: =BN27/(SUM($BM27:$BO27)) -> 0.12675407 | BU27: =BO27/(SUM($BM27:$BO27)) -> 0.35447028 | CE27: Grant | CF27: 1973 | CG27: 1506960 | CH27: 742948 | CI27: 17553 | CJ27: 77828 | CK27: 200744 | CL27: 0 | CM27: 200807 | CN27: 267080 | CO27: =SUM(CH27:CN27) -> 1506960 | CQ27: 0.823 | CR27: =CF27 -> 1973 | CS27: =(CG27-BK27)/BK27 -> 0.1239738 | CT27: =(CN27-BJ27)/BJ27 -> -9.3596151e-05
A28: =P28 -> Grant | B28: =L28 -> 1974 | C28: =M28 -> 350390 | D28: =N28 -> 1107885 | E28: =LN(D28/C28) -> 1.1511613 | F28: =A28 -> Grant | G28: 7258.634 | H28: =R28 -> 350315 | I28: =AA28 -> 958767.8 | J28: =LN(I28/H28) -> 1.0068162 | K28: =J28-(aa-bb*H28) -> 0.093436078 | L28: 1974 | M28: 350390 | N28: 1107885 | P28: =CE28 -> Grant | Q28: =CF28 -> 1974 | R28: =CN28 -> 350315 | S28: =CG28 -> 717854 | T28: =1-R28/S28 -> 0.51199687 | U28: =S28-R28 -> 367539 | W28: =$S31*W$2 -> 216760.8 | X28: =$S32*X$2 -> 711133.8 | Y28: =$S33*Y$2 -> 30873.2 | Z28: =$S34*Z$2 -> 0 | AA28: =SUM(W28:Z28) -> 958767.8 | AF28: =AA28 -> 958767.8 | AG28: =B28 -> 1974 | AH28: =W28/$AA28 -> 0.22608269 | AI28: =X28/$AA28 -> 0.7417164 | AJ28: =Y28/$AA28 -> 0.032200915 | AM28: =B28 -> 1974 | AN28: =AH25*AQ25+AI24*AQ24+AJ23*AQ23 -> 1143734 | AO28: =CHOOSE(umethod,T28,retroU,MAX(0,cslope*(AN28-nlim)/AN28)) -> 0.5 | AP28: =AN28*(1-AO28) -> 571867.02 | AQ28: =AP28*EXP(aa-bb*AP28+K28) -> 1365564.6 | AR28: =AN28-AP28 -> 571867.02 | AZ28: Cass | BA28: 1974 | BB28: 101667 | BC28: N/A | BD28: 28013 | BE28: 145411 | BF28: 1279 | BG28: 108257 | BH28: 384627 | BI28: 0.52 | BJ28: 350390 | BK28: 735017 | BL28: =BH28/BK28 -> 0.52328994 | BM28: =BB28/BK28 -> 0.13831925 | BN28: =BD28/(BK28-BB28) -> 0.044229889 | BO28: =BG28/(BK28-BB28-BD28-BF28) -> 0.17921623 | BP28: =BH28/BK28 -> 0.52328994 | BQ28: =BJ28*BP28/(1-BP28) -> 384627 | BS28: =BM28/(SUM($BM28:$BO28)) -> 0.38234519 | BT28: =BN28/(SUM($BM28:$BO28)) -> 0.12226126 | BU28: =BO28/(SUM($BM28:$BO28)) -> 0.49539356 | CE28: Grant | CF28: 1974 | CG28: 717854 | CH28: 87421 | CI28: 1151 | CJ28: 25560 | CK28: 145411 | CL28: 0 | CM28: 107996 | CN28: 350315 | CO28: =SUM(CH28:CN28) -> 717854 | CQ28: 0.512 | CR28: =CF28 -> 1974 | CS28: =(CG28-BK28)/BK28 -> -0.02335048 | CT28: =(CN28-BJ28)/BJ28 -> -0.0002140472
A29: =P29 -> Grant | B29: =L29 -> 1975 | C29: =M29 -> 191445 | D29: =N29 -> 527760 | E29: =LN(D29/C29) -> 1.0140411 | F29: =A29 -> Grant | G29: 7384.5171 | H29: =R29 -> 191420 | I29: =AA29 -> 631741.4 | J29: =LN(I29/H29) -> 1.1940102 | K29: =J29-(aa-bb*H29) -> 0.18280571 | L29: 1975 | M29: 191445 | N29: 527760 | P29: =CE29 -> Grant | Q29: =CF29 -> 1975 | R29: =CN29 -> 191420 | S29: =CG29 -> 486199 | T29: =1-R29/S29 -> 0.6062929 | U29: =S29-R29 -> 294779 | W29: =$S32*W$2 -> 355566.9 | X29: =$S33*X$2 -> 185239.2 | Y29: =$S34*Y$2 -> 90935.3 | Z29: =$S35*Z$2 -> 0 | AA29: =SUM(W29:Z29) -> 631741.4 | AF29: =AA29 -> 631741.4 | AG29: =B29 -> 1975 | AH29: =W29/$AA29 -> 0.56283615 | AI29: =X29/$AA29 -> 0.29321998 | AJ29: =Y29/$AA29 -> 0.14394387 | AM29: =B29 -> 1975 | AN29: =AH26*AQ26+AI25*AQ25+AJ24*AQ24 -> 641145.97 | AO29: =CHOOSE(umethod,T29,retroU,MAX(0,cslope*(AN29-nlim)/AN29)) -> 0.5 | AP29: =AN29*(1-AO29) -> 320572.99 | AQ29: =AP29*EXP(aa-bb*AP29+K29) -> 977117.17 | AR29: =AN29-AP29 -> 320572.99 | AZ29: Cass | BA29: 1975 | BB29: 144527 | BC29: N/A | BD29: 17876 | BE29: 69307 | BF29: 262 | BG29: 80560 | BH29: 312533 | BI29: 0.62 | BJ29: 191445 | BK29: 503978 | BL29: =BH29/BK29 -> 0.62013223 | BM29: =BB29/BK29 -> 0.28677244 | BN29: =BD29/(BK29-BB29) -> 0.049731396 | BO29: =BG29/(BK29-BB29-BD29-BF29) -> 0.23602969 | BP29: =BH29/BK29 -> 0.62013223 | BQ29: =BJ29*BP29/(1-BP29) -> 312533 | BS29: =BM29/(SUM($BM29:$BO29)) -> 0.50088323 | BT29: =BN29/(SUM($BM29:$BO29)) -> 0.086861981 | BU29: =BO29/(SUM($BM29:$BO29)) -> 0.41225479 | CE29: Grant | CF29: 1975 | CG29: 486199 | CH29: 124247 | CI29: 3950 | CJ29: 16433 | CK29: 69307 | CL29: 0 | CM29: 80842 | CN29: 191420 | CO29: =SUM(CH29:CN29) -> 486199 | CQ29: 0.606 | CR29: =CF29 -> 1975 | CS29: =(CG29-BK29)/BK29 -> -0.035277334 | CT29: =(CN29-BJ29)/BJ29 -> -0.00013058581
A30: =P30 -> Grant | B30: =L30 -> 1976 | C30: =M30 -> 340467 | D30: =N30 -> 761292 | E30: =LN(D30/C30) -> 0.80469879 | F30: =A30 -> Grant | G30: 7520.4064 | H30: =R30 -> 340517 | I30: =AA30 -> 688258.5 | J30: =LN(I30/H30) -> 0.70369944 | K30: =J30-(aa-bb*H30) -> -0.21571283 | L30: 1976 | M30: 340467 | N30: 761292 | P30: =CE30 -> Grant | Q30: =CF30 -> 1976 | R30: =CN30 -> 340517 | S30: =CG30 -> 1003722 | T30: =1-R30/S30 -> 0.6607457 | U30: =S30-R30 -> 663205 | W30: =$S33*W$2 -> 92619.6 | X30: =$S34*X$2 -> 545611.8 | Y30: =$S35*Y$2 -> 50027.1 | Z30: =$S36*Z$2 -> 0 | AA30: =SUM(W30:Z30) -> 688258.5 | AF30: =AA30 -> 688258.5 | AG30: =B30 -> 1976 | AH30: =W30/$AA30 -> 0.13457095 | AI30: =X30/$AA30 -> 0.79274255 | AJ30: =Y30/$AA30 -> 0.072686498 | AM30: =B30 -> 1976 | AN30: =AH27*AQ27+AI26*AQ26+AJ25*AQ25 -> 1880664.8 | AO30: =CHOOSE(umethod,T30,retroU,MAX(0,cslope*(AN30-nlim)/AN30)) -> 0.5 | AP30: =AN30*(1-AO30) -> 940332.38 | AQ30: =AP30*EXP(aa-bb*AP30+K30) -> 1313767.2 | AR30: =AN30-AP30 -> 940332.38 | AV30: Approx. | AW30: Approx. | AX30: Approx. | AZ30: Cass | BA30: 1976 | BB30: 343629 | BC30: N/A | BD30: 49645 | BE30: 191507 | BF30: 1126 | BG30: 187661 | BH30: 773568 | BI30: 0.69 | BJ30: 340467 | BK30: 1114035 | BL30: =BH30/BK30 -> 0.69438393 | BM30: =BB30/BK30 -> 0.3084544 | BN30: =BD30/(BK30-BB30) -> 0.064440048 | BO30: =BG30/(BK30-BB30-BD30-BF30) -> 0.26077247 | BP30: =BH30/BK30 -> 0.69438393 | BQ30: =BJ30*BP30/(1-BP30) -> 773568 | BS30: =BM30/(SUM($BM30:$BO30)) -> 0.48677687 | BT30: =BN30/(SUM($BM30:$BO30)) -> 0.10169388 | BU30: =BO30/(SUM($BM30:$BO30)) -> 0.41152925 | CE30: Grant | CF30: 1976 | CG30: 1003722 | CH30: 237524 | CI30: 4559 | CJ30: 43244 | CK30: 191507 | CL30: 0 | CM30: 186371 | CN30: 340517 | CO30: =SUM(CH30:CN30) -> 1003722 | CQ30: 0.661 | CR30: =CF30 -> 1976 | CS30: =(CG30-BK30)/BK30 -> -0.099021126 | CT30: =(CN30-BJ30)/BJ30 -> 0.00014685711
A31: =P31 -> Grant | B31: =L31 -> 1977 | C31: =M31 -> 599371 | D31: =N31 -> 583647 | E31: =LN(D31/C31) -> -0.026584424 | F31: =A31 -> Grant | G31: 7667.097 | H31: =R31 -> 599341 | I31: =AA31 -> 645369.6 | J31: =LN(I31/H31) -> 0.073992458 | K31: =J31-(aa-bb*H31) -> -0.68607375 | L31: 1977 | M31: 599371 | N31: 583647 | P31: =CE31 -> Grant | Q31: =CF31 -> 1977 | R31: =CN31 -> 599341 | S31: =CG31 -> 722536 | T31: =1-R31/S31 -> 0.17050362 | U31: =S31-R31 -> 123195 | W31: =$S34*W$2 -> 272805.9 | X31: =$S35*X$2 -> 300162.6 | Y31: =$S36*Y$2 -> 72401.1 | Z31: =$S37*Z$2 -> 0 | AA31: =SUM(W31:Z31) -> 645369.6 | AF31: =AA31 -> 645369.6 | AG31: =B31 -> 1977 | AH31: =W31/$AA31 -> 0.42271266 | AI31: =X31/$AA31 -> 0.46510186 | AJ31: =Y31/$AA31 -> 0.11218548 | AM31: =B31 -> 1977 | AN31: =AH28*AQ28+AI27*AQ27+AJ26*AQ26 -> 1543191.2 | AO31: =CHOOSE(umethod,T31,retroU,MAX(0,cslope*(AN31-nlim)/AN31)) -> 0.5 | AP31: =AN31*(1-AO31) -> 771595.61 | AQ31: =AP31*EXP(aa-bb*AP31+K31) -> 747252.98 | AR31: =AN31-AP31 -> 771595.61 | AS31: Source | AU31: Fraser R | AV31: Fraser R | AW31: Total HR | AX31: total return | AY31: %dif with Grant | AZ31: Cass | BA31: 1977 | BB31: 42066 | BC31: N/A | BD31: 8228 | BE31: 38846 | BF31: 626 | BG31: 23728 | BH31: 113494 | BI31: 0.16 | BJ31: 599371 | BK31: 712865 | BL31: =BH31/BK31 -> 0.15920827 | BM31: =BB31/BK31 -> 0.05900977 | BN31: =BD31/(BK31-BB31) -> 0.012265969 | BO31: =BG31/(BK31-BB31-BD31-BF31) -> 0.035845878 | BP31: =BH31/BK31 -> 0.15920827 | BQ31: =BJ31*BP31/(1-BP31) -> 113494 | BS31: =BM31/(SUM($BM31:$BO31)) -> 0.55086706 | BT31: =BN31/(SUM($BM31:$BO31)) -> 0.11450508 | BU31: =BO31/(SUM($BM31:$BO31)) -> 0.33462787 | CE31: Grant | CF31: 1977 | CG31: 722536 | CH31: 54997 | CI31: 0 | CJ31: 6358 | CK31: 36660 | CL31: 0 | CM31: 25180 | CN31: 599341 | CO31: =SUM(CH31:CN31) -> 722536 | CQ31: 0.171 | CR31: =CF31 -> 1977 | CS31: =(CG31-BK31)/BK31 -> 0.013566384 | CT31: =(CN31-BJ31)/BJ31 -> -5.0052472e-05
A32: =P32 -> Grant | B32: =L32 -> 1978 | C32: =M32 -> 359065 | D32: =N32 -> 635560 | E32: =LN(D32/C32) -> 0.57100307 | F32: =A32 -> Grant | G32: 7825.4477 | H32: =R32 -> 358990 | I32: =AA32 -> 631498 | J32: =LN(I32/H32) -> 0.56480024 | K32: =J32-(aa-bb*H32) -> -0.34323905 | L32: 1978 | M32: 359065 | N32: 635560 | P32: =CE32 -> Grant | Q32: =CF32 -> 1978 | R32: =CN32 -> 358990 | S32: =CG32 -> 1185223 | T32: =1-R32/S32 -> 0.69711185 | U32: =S32-R32 -> 826233 | W32: =$S35*W$2 -> 150081.3 | X32: =$S36*X$2 -> 434406.6 | Y32: =$S37*Y$2 -> 47010.1 | Z32: =$S38*Z$2 -> 0 | AA32: =SUM(W32:Z32) -> 631498 | AF32: =AA32 -> 631498 | AG32: =B32 -> 1978 | AH32: =W32/$AA32 -> 0.23765918 | AI32: =X32/$AA32 -> 0.68789862 | AJ32: =Y32/$AA32 -> 0.074442199 | AM32: =B32 -> 1978 | AN32: =AH29*AQ29+AI28*AQ28+AJ27*AQ27 -> 1867507.6 | AO32: =CHOOSE(umethod,T32,retroU,MAX(0,cslope*(AN32-nlim)/AN32)) -> 0.5 | AP32: =AN32*(1-AO32) -> 933753.8 | AQ32: =AP32*EXP(aa-bb*AP32+K32) -> 1153040.2 | AR32: =AN32-AP32 -> 933753.8 | AT32: broodyear | AU32: spawners | AV32: total catch | AW32: HR | AZ32: Cass | BA32: 1978 | BB32: 485439 | BC32: N/A | BD32: 12318 | BE32: 295733 | BF32: 277 | BG32: 134260 | BH32: 928027 | BI32: 0.72 | BJ32: 359065 | BK32: 1287092 | BL32: =BH32/BK32 -> 0.72102616 | BM32: =BB32/BK32 -> 0.37715952 | BN32: =BD32/(BK32-BB32) -> 0.015365751 | BO32: =BG32/(BK32-BB32-BD32-BF32) -> 0.17015226 | BP32: =BH32/BK32 -> 0.72102616 | BQ32: =BJ32*BP32/(1-BP32) -> 928027 | BS32: =BM32/(SUM($BM32:$BO32)) -> 0.67029426 | BT32: =BN32/(SUM($BM32:$BO32)) -> 0.027308271 | BU32: =BO32/(SUM($BM32:$BO32)) -> 0.30239746 | CE32: Grant | CF32: 1978 | CG32: 1185223 | CH32: 405890 | CI32: 729 | CJ32: 11113 | CK32: 273516 | CL32: 0 | CM32: 134985 | CN32: 358990 | CO32: =SUM(CH32:CN32) -> 1185223 | CQ32: 0.697 | CR32: =CF32 -> 1978 | CS32: =(CG32-BK32)/BK32 -> -0.079146634 | CT32: =(CN32-BJ32)/BJ32 -> -0.00020887583 | CW32: broodyear | CX32: spawners | CY32: recruits | CZ32: %dif Spa | DA32: %dif Rec
A33: =P33 -> Grant | B33: =L33 -> 1979 | C33: =M33 -> 255634 | D33: =N33 -> 510199 | E33: =LN(D33/C33) -> 0.69105411 | F33: =A33 -> Grant | G33: 7996.3852 | H33: =R33 -> 255634 | I33: =AA33 -> 560544.2 | J33: =LN(I33/H33) -> 0.78516136 | K33: =J33-(aa-bb*H33) -> -0.18650947 | L33: 1979 | M33: 255634 | N33: 510199 | P33: =CE33 -> Grant | Q33: =CF33 -> 1979 | R33: =CN33 -> 255634 | S33: =CG33 -> 308732 | T33: =1-R33/S33 -> 0.17198735 | U33: =S33-R33 -> 53098 | W33: =$S36*W$2 -> 217203.3 | X33: =$S37*X$2 -> 282060.6 | Y33: =$S38*Y$2 -> 61280.3 | Z33: =$S39*Z$2 -> 0 | AA33: =SUM(W33:Z33) -> 560544.2 | AF33: =AA33 -> 560544.2 | AG33: =B33 -> 1979 | AH33: =W33/$AA33 -> 0.38748648 | AI33: =X33/$AA33 -> 0.50319065 | AJ33: =Y33/$AA33 -> 0.10932287 | AM33: =B33 -> 1979 | AN33: =AH30*AQ30+AI29*AQ29+AJ28*AQ28 -> 507277.61 | AO33: =CHOOSE(umethod,T33,retroU,MAX(0,cslope*(AN33-nlim)/AN33)) -> 0.5 | AP33: =AN33*(1-AO33) -> 253638.8 | AQ33: =AP33*EXP(aa-bb*AP33+K33) -> 556852.8 | AR33: =AN33-AP33 -> 253638.8 | AS33: Cass | AT33: 1979 | AU33: 255634 | AV33: =BH33 -> 42262 | AW33: =AV33/(AU33+AV33) -> 0.1418683 | AX33: =AU33+AV33 -> 297896 | AY33: =(AX33-CG33)/CG33 -> -0.035098402 | AZ33: Cass | BA33: 1979 | BB33: 20326 | BC33: N/A | BD33: 2105 | BE33: 3455 | BF33: 403 | BG33: 15973 | BH33: 42262 | BI33: 0.14 | BJ33: 255634 | BK33: 297896 | BL33: =BH33/BK33 -> 0.1418683 | BM33: =BB33/BK33 -> 0.068231866 | BN33: =BD33/(BK33-BB33) -> 0.0075836726 | BO33: =BG33/(BK33-BB33-BD33-BF33) -> 0.058070544 | BP33: =BH33/BK33 -> 0.1418683 | BQ33: =BJ33*BP33/(1-BP33) -> 42262 | BR33: Harvest Rate | BS33: =BM33/(SUM($BM33:$BO33)) -> 0.50962628 | BT33: =BN33/(SUM($BM33:$BO33)) -> 0.056642725 | BU33: =BO33/(SUM($BM33:$BO33)) -> 0.433731 | BW33: Year | BX33: Spawners | BY33: Harvest | BZ33: Harvest Rate d2 | CA33: Returns | CC33: Harvest Rate d1 | CE33: Grant | CF33: 1979 | CG33: 308732 | CH33: 31093 | CI33: 0 | CJ33: 1381 | CK33: 3321 | CL33: 0 | CM33: 17304 | CN33: 255634 | CO33: =SUM(CH33:CN33) -> 308733 | CQ33: 0.172 | CR33: =CF33 -> 1979 | CS33: =(CG33-BK33)/BK33 -> 0.036375111 | CT33: =(CN33-BJ33)/BJ33 -> 0 | CW33: 1979 | CX33: 255634 | CY33: 510199 | CZ33: =(CX33-R33)/R33 -> 0 | DA33: =(CY33-AF33)/AF33 -> -0.089814862
A34: =P34 -> Grant | B34: =L34 -> 1980 | C34: =M34 -> 312182 | D34: =N34 -> 655505 | E34: =LN(D34/C34) -> 0.74181958 | F34: =A34 -> Grant | G34: 8180.9099 | H34: =R34 -> 314011 | I34: =AA34 -> 692616.5 | J34: =LN(I34/H34) -> 0.79104844 | K34: =J34-(aa-bb*H34) -> -0.14468236 | L34: 1980 | M34: 312182 | N34: 655505 | P34: =CE34 -> Grant | Q34: =CF34 -> 1980 | R34: =CN34 -> 314011 | S34: =CG34 -> 909353 | T34: =1-R34/S34 -> 0.65468745 | U34: =S34-R34 -> 595342 | W34: =$S37*W$2 -> 141030.3 | X34: =$S38*X$2 -> 367681.8 | Y34: =$S39*Y$2 -> 183904.4 | Z34: =$S40*Z$2 -> 0 | AA34: =SUM(W34:Z34) -> 692616.5 | AF34: =AA34 -> 692616.5 | AG34: =B34 -> 1980 | AH34: =W34/$AA34 -> 0.20361961 | AI34: =X34/$AA34 -> 0.53085914 | AJ34: =Y34/$AA34 -> 0.26552125 | AM34: =B34 -> 1980 | AN34: =AH31*AQ31+AI30*AQ30+AJ29*AQ29 -> 1498002.5 | AO34: =CHOOSE(umethod,T34,retroU,MAX(0,cslope*(AN34-nlim)/AN34)) -> 0.5 | AP34: =AN34*(1-AO34) -> 749001.26 | AQ34: =AP34*EXP(aa-bb*AP34+K34) -> 1263935.5 | AR34: =AN34-AP34 -> 749001.26 | AS34: Cass | AT34: 1980 | AU34: 312182 | AV34: =BH34 -> 594711 | AW34: =AV34/(AU34+AV34) -> 0.65576755 | AX34: =AU34+AV34 -> 906893 | AY34: =(AX34-CG34)/CG34 -> -0.0027052201 | AZ34: Cass | BA34: 1980 | BB34: 243146 | BC34: N/A | BD34: 13550 | BE34: 245019 | BF34: 3666 | BG34: 89330 | BH34: 594711 | BI34: =BH34/BK34 -> 0.65576755 | BJ34: 312182 | BK34: 906893 | BL34: =BH34/BK34 -> 0.65576755 | BM34: =BB34/BK34 -> 0.26810881 | BN34: =BD34/(BK34-BB34) -> 0.020414405 | BO34: =BG34/(BK34-BB34-BD34-BF34) -> 0.13816816 | BP34: =BH34/BK34 -> 0.65576755 | BQ34: =BJ34*BP34/(1-BP34) -> 594711 | BR34: 0.51937603 | BS34: =BM34/(SUM($BM34:$BO34)) -> 0.62834363 | BT34: =BN34/(SUM($BM34:$BO34)) -> 0.047843491 | BU34: =BO34/(SUM($BM34:$BO34)) -> 0.32381288 | BW34: 1980 | BX34: 1373377 | BY34: 1162099.8 | BZ34: 0.45833581 | CA34: 2535476.8 | CC34: =BI34 -> 0.65576755 | CE34: Grant | CF34: 1980 | CG34: 909353 | CH34: 242556 | CI34: 8546 | CJ34: 12026 | CK34: 241835 | CL34: 0 | CM34: 90380 | CN34: 314011 | CO34: =SUM(CH34:CN34) -> 909354 | CQ34: 0.655 | CR34: =CF34 -> 1980 | CS34: =(CG34-BK34)/BK34 -> 0.0027125582 | CT34: =(CN34-BJ34)/BJ34 -> 0.0058587619 | CW34: 1980 | CX34: 312182 | CY34: 655505 | CZ34: =(CX34-R34)/R34 -> -0.0058246367 | DA34: =(CY34-AF34)/AF34 -> -0.0535816
