Workbook
Name alphaV: 'Retrospective Run1'!$AH$9
Name ar: 'lag 1 autocorr model'!$G$2
Name br: 'lag 1 autocorr model'!$G$3
Name byrate: 'Retrospective Run1'!$AI$11
Name chilcotSSLz: covariates!$V$85
Name deltaPred: 'Retrospective Run1'!$AY$10
Name Fnbycatch: 'Retrospective Run1'!$AJ$7
Name ndata: 'Retrospective Run1'!$AY$1
Name ndatachum: 'Retrospective Run1'!$C$105
Name ndatatot: 'Retrospective Run1'!$AZ$109
Name negLL: 'lag 1 autocorr model'!$G$6
Name rho: 'lag 1 autocorr model'!$G$5
Name rundays: 'Retrospective Run1'!$FQ$8
Name sdtot: 'Retrospective Run1'!$AZ$111
Name sige: 'lag 1 autocorr model'!$G$6
Name sigev: 'lag 1 autocorr model'!$G$9
Name sigmaCH: 'Retrospective Run1'!$AY$7
Name sigmaTH: 'Retrospective Run1'!$AY$6
Name sigr: 'lag 1 autocorr model'!$G$4
Name SSLavg: covariates!$V$3
Name SSLavgCH: covariates!$AD$3
Name sslavgTH: covariates!$AC$3
Name SSLcontrol: 'Retrospective Run1'!$AI$10
Name SSLsd: covariates!$V$4
Name SSLsdCH: covariates!$AD$4
Name SSLsdTH: covariates!$AC$4
Name SSLz: 'Retrospective Run1'!$FD$9
Name sumsqchum: 'Retrospective Run1'!$C$104
Name thompSSLz: covariates!$V$84
Name Uapply: 'Retrospective Run1'!$AJ$9
Name Uhistoric: 'Retrospective Run1'!$AJ$8

Sheet Orig data
S1: Age 3 | T1: Age 4 | U1: Age 5 | V1: Age 6
G2: Best S-R data | S2: 0.10741517 | T2: 0.75930234 | U2: 0.13183604 | V2: 0.0014464538
A3: Cass, Grant, Digitized, Haley's S/R | G3: Using age prop. by yr from 1996-2017 | J3: Haley's Best S/R | P3: BEST | Q3: BEST | S3: recruits produced at age from Brood Year | AM3: Johnstone | AN3: Georgia. | AO3: West | AQ3: U.S. | AR3: All Fraser | AS3: Total | AT3: Harvest | AU3: Gross (d) | AV3: Total | AX3: Johnstone | AY3: West Coast | BD3: Johnstone | BE3: West Coast
A4: Source | B4: Brood year | C4: Spawners (D) | D4: Haley's Recruits with some infill from mkm | E4: ln(R/S)(H) | F4: Source | G4: Spawners (D) | H4: Recruits | I4: ln(R/S)(D) | J4: broodyear | K4: spawners | L4: recruits | N4: Source | O4: Year | P4: Gross Escapement | Q4: total Stock, hr from Grant then Brittany | R4: tot stock digitized from DFO 2023 | S4: Age 3 | T4: Age 4 | U4: Age 5 | V4: Age 6 | W4: Recruits | AB4: Improved recruits starting 1990 | AK4: Source | AL4: Year | AM4: Strait (a) | AN4: Strait | AO4: Coast (b) | AP4: 7&7A | AQ4: 4B,5,6C | AR4: Harvest (c) | AS4: Harvest | AT4: Rate | AU4: Escapement | AV4: Stock | AW4: HR | AX4: St. HR | AY4: HR | AZ4: Fraser R HR | BA4: hr | BB4: catch | BD4: St. HR | BE4: HR | BF4: Fraser R HR
A5: =N5 -> Cass | B5: =J5 -> 1951 | C5: =K5 -> 171725 | D5: =L5 -> 498986 | E5: =LN(D5/C5) -> 1.0666837 | F5: =A5 -> Cass | G5: =P5 -> 171725 | H5: =W5 -> 457007.21 | I5: =LN(H5/G5) -> 0.97880481 | J5: 1951 | K5: 171725 | L5: 498986 | N5: =AK5 -> Cass | O5: =AL5 -> 1951 | P5: =AU5 -> 171725 | Q5: =AV5 -> 1187739 | S5: =$Q8*S$2 -> 117782.55 | T5: =$Q9*T$2 -> 301518.2 | U5: =$Q10*U$2 -> 37260.425 | V5: =$Q11*V$2 -> 446.03283 | W5: =SUM(S5:V5) -> 457007.21 | AB5: =W5 -> 457007.21 | AK5: Cass | AL5: 1951 | AM5: 523874 | AN5: N/A | AO5: 302 | AP5: 0 | AQ5: 23 | AR5: 491815 | AS5: 1016014 | AT5: 0.86 | AU5: 171725 | AV5: 1187739 | AW5: =AS5/AV5 -> 0.85541857 | AX5: =AM5/AV5 -> 0.44106828 | AY5: =AO5/(AV5-AM5) -> 0.00045491177 | AZ5: =AR5/(AV5-AM5-AO5-AQ5) -> 0.74119872 | BA5: =AS5/AV5 -> 0.85541857 | BB5: =AU5*BA5/(1-BA5) -> 1016014 | BD5: =AX5/(SUM($AX5:$AZ5)) -> 0.37292645 | BE5: =AY5/(SUM($AX5:$AZ5)) -> 0.00038463121 | BF5: =AZ5/(SUM($AX5:$AZ5)) -> 0.62668892 | CC5: Grant vs. Cass
A6: =N6 -> Cass | B6: =J6 -> 1952 | C6: =K6 -> 176250 | D6: =L6 -> 283055 | E6: =LN(D6/C6) -> 0.47373778 | F6: =A6 -> Cass | G6: =P6 -> 176250 | H6: =W6 -> 298716.92 | I6: =LN(H6/G6) -> 0.52759293 | J6: 1952 | K6: 176250 | L6: 283055 | N6: =AK6 -> Cass | O6: =AL6 -> 1952 | P6: =AU6 -> 176250 | Q6: =AV6 -> 927000 | S6: =$Q9*S$2 -> 42654.455 | T6: =$Q10*T$2 -> 214599.34 | U6: =$Q11*U$2 -> 40653.358 | V6: =$Q12*V$2 -> 809.76678 | W6: =SUM(S6:V6) -> 298716.92 | AB6: =W6 -> 298716.92 | AK6: Cass | AL6: 1952 | AM6: 191249 | AN6: N/A | AO6: 108 | AP6: 0 | AQ6: 0 | AR6: 559393 | AS6: 750750 | AT6: 0.81 | AU6: 176250 | AV6: 927000 | AW6: =AS6/AV6 -> 0.80987055 | AX6: =AM6/AV6 -> 0.2063096 | AY6: =AO6/(AV6-AM6) -> 0.00014678879 | AZ6: =AR6/(AV6-AM6-AO6-AQ6) -> 0.76041368 | BA6: =AS6/AV6 -> 0.80987055 | BB6: =AU6*BA6/(1-BA6) -> 750750 | BD6: =AX6/(SUM($AX6:$AZ6)) -> 0.21337883 | BE6: =AY6/(SUM($AX6:$AZ6)) -> 0.00015181853 | BF6: =AZ6/(SUM($AX6:$AZ6)) -> 0.78646935 | BP6: Source | BQ6: Year | BR6: Total Returns | BS6: Areas 11 to 13 | BT6: Area 14 | BU6: Areas 20 & 21 | BV6: Areas 7 & 7a | BW6: Areas 4b, 5, 6c | BX6: Fraser | BY6: Gross Escapement | BZ6: Gross Esc+catch | CB6: Total exploitation rate | CC6: Year | CD6: %dif tot returns | CE6: %dif gross escape
A7: =N7 -> Grant | B7: =J7 -> 1953 | C7: =K7 -> 137225 | D7: =L7 -> 312122 | E7: =LN(D7/C7) -> 0.82177222 | F7: =A7 -> Grant | G7: =P7 -> 137625 | H7: =W7 -> 339247.35 | I7: =LN(H7/G7) -> 0.9021969 | J7: 1953 | K7: 137225 | L7: 312122 | N7: =BP7 -> Grant | O7: =BQ7 -> 1953 | P7: =BY7 -> 137625 | Q7: =BR7 -> 918122 | S7: =$Q10*S$2 -> 30358.426 | T7: =$Q11*T$2 -> 234140.75 | U7: =$Q12*U$2 -> 73805.64 | V7: =$Q13*V$2 -> 942.54112 | W7: =SUM(S7:V7) -> 339247.35 | AB7: =W7 -> 339247.35 | AK7: Cass | AL7: 1953 | AM7: 465021 | AN7: N/A | AO7: 404 | AP7: 0 | AQ7: 0 | AR7: 331804 | AS7: 797229 | AT7: 0.85 | AU7: 137225 | AV7: 934454 | AW7: =AS7/AV7 -> 0.85314954 | AX7: =AM7/AV7 -> 0.49763926 | AY7: =AO7/(AV7-AM7) -> 0.0008606127 | AZ7: =AR7/(AV7-AM7-AO7-AQ7) -> 0.70742747 | BA7: =AS7/AV7 -> 0.85314954 | BB7: =AU7*BA7/(1-BA7) -> 797229 | BD7: =AX7/(SUM($AX7:$AZ7)) -> 0.41266106 | BE7: =AY7/(SUM($AX7:$AZ7)) -> 0.00071365219 | BF7: =AZ7/(SUM($AX7:$AZ7)) -> 0.58662528 | BP7: Grant | BQ7: 1953 | BR7: 918122 | BS7: 434551 | BT7: 10184 | BU7: 3947 | BV7: 0 | BW7: 0 | BX7: 331815 | BY7: 137625 | BZ7: =SUM(BS7:BY7) -> 918122 | CB7: 0.85 | CC7: =BQ7 -> 1953 | CD7: =(BR7-AV7)/AV7 -> -0.017477586 | CE7: =(BY7-AU7)/AU7 -> 0.0029149208
A8: =N8 -> Grant | B8: =J8 -> 1954 | C8: =K8 -> 86375 | D8: =L8 -> 504589 | E8: =LN(D8/C8) -> 1.765046 | F8: =A8 -> Grant | G8: =P8 -> 86375 | H8: =W8 -> 544674.75 | I8: =LN(H8/G8) -> 1.8414905 | J8: 1954 | K8: 86375 | L8: 504589 | N8: =BP8 -> Grant | O8: =BQ8 -> 1954 | P8: =BY8 -> 86375 | Q8: =BR8 -> 1096517 | S8: =$Q11*S$2 -> 33122.863 | T8: =$Q12*T$2 -> 425079.47 | U8: =$Q13*U$2 -> 85907.266 | V8: =$Q14*V$2 -> 565.14975 | W8: =SUM(S8:V8) -> 544674.75 | AB8: =W8 -> 544674.75 | AK8: Cass | AL8: 1954 | AM8: 590473 | AN8: N/A | AO8: 253 | AP8: 0 | AQ8: 0 | AR8: 457750 | AS8: 1048476 | AT8: 0.92 | AU8: 86375 | AV8: 1134851 | AW8: =AS8/AV8 -> 0.92388869 | AX8: =AM8/AV8 -> 0.52030883 | AY8: =AO8/(AV8-AM8) -> 0.0004647506 | AZ8: =AR8/(AV8-AM8-AO8-AQ8) -> 0.8412589 | BA8: =AS8/AV8 -> 0.92388869 | BB8: =AU8*BA8/(1-BA8) -> 1048476 | BD8: =AX8/(SUM($AX8:$AZ8)) -> 0.38200912 | BE8: =AY8/(SUM($AX8:$AZ8)) -> 0.00034121844 | BF8: =AZ8/(SUM($AX8:$AZ8)) -> 0.61764966 | BP8: Grant | BQ8: 1954 | BR8: 1096517 | BS8: 542719 | BT8: 8768 | BU8: 1248 | BV8: 0 | BW8: 0 | BX8: 457407 | BY8: 86375 | BZ8: =SUM(BS8:BY8) -> 1096517 | CB8: 0.921 | CC8: =BQ8 -> 1954 | CD8: =(BR8-AV8)/AV8 -> -0.033778884 | CE8: =(BY8-AU8)/AU8 -> 0
A9: =N9 -> Grant | B9: =J9 -> 1955 | C9: =K9 -> 110500 | D9: =L9 -> 592568 | E9: =LN(D9/C9) -> 1.6794501 | F9: =A9 -> Grant | G9: =P9 -> 110500 | H9: =W9 -> 606789.3 | I9: =LN(H9/G9) -> 1.7031661 | J9: 1955 | K9: 110500 | L9: 592568 | N9: =BP9 -> Grant | O9: =BQ9 -> 1955 | P9: =BY9 -> 110500 | Q9: =BR9 -> 397099 | S9: =$Q12*S$2 -> 60134.125 | T9: =$Q13*T$2 -> 494778.11 | U9: =$Q14*U$2 -> 51510.188 | V9: =$Q15*V$2 -> 366.88433 | W9: =SUM(S9:V9) -> 606789.3 | AB9: =W9 -> 606789.3 | AK9: Cass | AL9: 1955 | AM9: 143565 | AN9: N/A | AO9: 759 | AP9: 0 | AQ9: 9 | AR9: 103297 | AS9: 247630 | AT9: 0.69 | AU9: 110500 | AV9: 358130 | AW9: =AS9/AV9 -> 0.69145282 | AX9: =AM9/AV9 -> 0.40087398 | AY9: =AO9/(AV9-AM9) -> 0.0035373896 | AZ9: =AR9/(AV9-AM9-AO9-AQ9) -> 0.48315458 | BA9: =AS9/AV9 -> 0.69145282 | BB9: =AU9*BA9/(1-BA9) -> 247630 | BD9: =AX9/(SUM($AX9:$AZ9)) -> 0.45165543 | BE9: =AY9/(SUM($AX9:$AZ9)) -> 0.0039854949 | BF9: =AZ9/(SUM($AX9:$AZ9)) -> 0.54435907 | BP9: Grant | BQ9: 1955 | BR9: 397099 | BS9: 174665 | BT9: 634 | BU9: 8217 | BV9: 0 | BW9: 0 | BX9: 103084 | BY9: 110500 | BZ9: =SUM(BS9:BY9) -> 397100 | CB9: 0.722 | CC9: =BQ9 -> 1955 | CD9: =(BR9-AV9)/AV9 -> 0.10881244 | CE9: =(BY9-AU9)/AU9 -> 0
A10: =N10 -> Grant | B10: =J10 -> 1956 | C10: =K10 -> 32925 | D10: =L10 -> 518932 | E10: =LN(D10/C10) -> 2.7575406 | F10: =A10 -> Grant | G10: =P10 -> 32950 | H10: =W10 -> 400464.07 | I10: =LN(H10/G10) -> 2.4976328 | J10: 1956 | K10: 32925 | L10: 518932 | N10: =BP10 -> Grant | O10: =BQ10 -> 1956 | P10: =BY10 -> 32950 | Q10: =BR10 -> 282627 | S10: =$Q13*S$2 -> 69994.085 | T10: =$Q14*T$2 -> 296670.05 | U10: =$Q15*U$2 -> 33439.421 | V10: =$Q16*V$2 -> 360.5127 | W10: =SUM(S10:V10) -> 400464.07 | AB10: =W10 -> 400464.07 | AK10: Cass | AL10: 1956 | AM10: 155668 | AN10: N/A | AO10: 61 | AP10: 0 | AQ10: 0 | AR10: 72958 | AS10: 228687 | AT10: 0.87 | AU10: 32925 | AV10: 261612 | AW10: =AS10/AV10 -> 0.87414568 | AX10: =AM10/AV10 -> 0.59503387 | AY10: =AO10/(AV10-AM10) -> 0.00057577588 | AZ10: =AR10/(AV10-AM10-AO10-AQ10) -> 0.68904357 | BA10: =AS10/AV10 -> 0.87414568 | BB10: =AU10*BA10/(1-BA10) -> 228687 | BD10: =AX10/(SUM($AX10:$AZ10)) -> 0.46318638 | BE10: =AY10/(SUM($AX10:$AZ10)) -> 0.00044819557 | BF10: =AZ10/(SUM($AX10:$AZ10)) -> 0.53636543 | BP10: Grant | BQ10: 1956 | BR10: 282627 | BS10: 175589 | BT10: 685 | BU10: 591 | BV10: 0 | BW10: 0 | BX10: 72812 | BY10: 32950 | BZ10: =SUM(BS10:BY10) -> 282627 | CB10: 0.883 | CC10: =BQ10 -> 1956 | CD10: =(BR10-AV10)/AV10 -> 0.080328884 | CE10: =(BY10-AU10)/AU10 -> 0.00075930144
A11: =N11 -> Grant | B11: =J11 -> 1957 | C11: =K11 -> 84630 | D11: =L11 -> 353281 | E11: =LN(D11/C11) -> 1.428975 | F11: =A11 -> Grant | G11: =P11 -> 84655 | H11: =W11 -> 267911.4 | I11: =LN(H11/G11) -> 1.1520722 | J11: 1957 | K11: 84630 | L11: 353281 | N11: =BP11 -> Grant | O11: =BQ11 -> 1957 | P11: =BY11 -> 84655 | Q11: =BR11 -> 308363 | S11: =$Q14*S$2 -> 41968.609 | T11: =$Q15*T$2 -> 192592.48 | U11: =$Q16*U$2 -> 32858.683 | V11: =$Q17*V$2 -> 491.6265 | W11: =SUM(S11:V11) -> 267911.4 | AB11: =W11 -> 267911.4 | AK11: Cass | AL11: 1957 | AM11: 92528 | AN11: N/A | AO11: 123 | AP11: 0 | AQ11: 48 | AR11: 124319 | AS11: 217018 | AT11: 0.72 | AU11: 84630 | AV11: 301648 | AW11: =AS11/AV11 -> 0.7194412 | AX11: =AM11/AV11 -> 0.30674163 | AY11: =AO11/(AV11-AM11) -> 0.00058817904 | AZ11: =AR11/(AV11-AM11-AO11-AQ11) -> 0.59497294 | BA11: =AS11/AV11 -> 0.7194412 | BB11: =AU11*BA11/(1-BA11) -> 217018 | BD11: =AX11/(SUM($AX11:$AZ11)) -> 0.33995423 | BE11: =AY11/(SUM($AX11:$AZ11)) -> 0.0006518644 | BF11: =AZ11/(SUM($AX11:$AZ11)) -> 0.65939391 | BP11: Grant | BQ11: 1957 | BR11: 308363 | BS11: 97399 | BT11: 600 | BU11: 1444 | BV11: 0 | BW11: 0 | BX11: 124265 | BY11: 84655 | BZ11: =SUM(BS11:BY11) -> 308363 | CB11: 0.725 | CC11: =BQ11 -> 1957 | CD11: =(BR11-AV11)/AV11 -> 0.022261046 | CE11: =(BY11-AU11)/AU11 -> 0.00029540352
A12: =N12 -> Grant | B12: =J12 -> 1958 | C12: =K12 -> 89375 | D12: =L12 -> 302174 | E12: =LN(D12/C12) -> 1.218162 | F12: =A12 -> Grant | G12: =P12 -> 89400 | H12: =W12 -> 261839.37 | I12: =LN(H12/G12) -> 1.0746105 | J12: 1958 | K12: 89375 | L12: 302174 | N12: =BP12 -> Grant | O12: =BQ12 -> 1958 | P12: =BY12 -> 89400 | Q12: =BR12 -> 559829 | S12: =$Q15*S$2 -> 27245.212 | T12: =$Q16*T$2 -> 189247.76 | U12: =$Q17*U$2 -> 44808.962 | V12: =$Q18*V$2 -> 537.43859 | W12: =SUM(S12:V12) -> 261839.37 | AB12: =W12 -> 261839.37 | AK12: Cass | AL12: 1958 | AM12: 252287 | AN12: N/A | AO12: 1178 | AP12: 0 | AQ12: 690 | AR12: 202075 | AS12: 456230 | AT12: 0.84 | AU12: 89375 | AV12: 545605 | AW12: =AS12/AV12 -> 0.83619102 | AX12: =AM12/AV12 -> 0.46239862 | AY12: =AO12/(AV12-AM12) -> 0.004016119 | AZ12: =AR12/(AV12-AM12-AO12-AQ12) -> 0.69334363 | BA12: =AS12/AV12 -> 0.83619102 | BB12: =AU12*BA12/(1-BA12) -> 456230 | BD12: =AX12/(SUM($AX12:$AZ12)) -> 0.39870255 | BE12: =AY12/(SUM($AX12:$AZ12)) -> 0.0034628929 | BF12: =AZ12/(SUM($AX12:$AZ12)) -> 0.59783455 | BP12: Grant | BQ12: 1958 | BR12: 559829 | BS12: 247648 | BT12: 8879 | BU12: 11935 | BV12: 0 | BW12: 0 | BX12: 201968 | BY12: 89400 | BZ12: =SUM(BS12:BY12) -> 559830 | CB12: 0.84 | CC12: =BQ12 -> 1958 | CD12: =(BR12-AV12)/AV12 -> 0.026070142 | CE12: =(BY12-AU12)/AU12 -> 0.00027972028
A13: =N13 -> Grant | B13: =J13 -> 1959 | C13: =K13 -> 152300 | D13: =L13 -> 361837 | E13: =LN(D13/C13) -> 0.86534157 | F13: =A13 -> Grant | G13: =P13 -> 152300 | H13: =W13 -> 334077.82 | I13: =LN(H13/G13) -> 0.78552169 | J13: 1959 | K13: 152300 | L13: 361837 | N13: =BP13 -> Grant | O13: =BQ13 -> 1959 | P13: =BY13 -> 152300 | Q13: =BR13 -> 651622 | S13: =$Q16*S$2 -> 26772.048 | T13: =$Q17*T$2 -> 258074.72 | U13: =$Q18*U$2 -> 48984.473 | V13: =$Q19*V$2 -> 246.57987 | W13: =SUM(S13:V13) -> 334077.82 | AB13: =W13 -> 334077.82 | AK13: Cass | AL13: 1959 | AM13: 218898 | AN13: N/A | AO13: 1448 | AP13: 0 | AQ13: 996 | AR13: 237091 | AS13: 458433 | AT13: 0.75 | AU13: 152300 | AV13: 610733 | AW13: =AS13/AV13 -> 0.75062752 | AX13: =AM13/AV13 -> 0.35841849 | AY13: =AO13/(AV13-AM13) -> 0.003695433 | AZ13: =AR13/(AV13-AM13-AO13-AQ13) -> 0.60887642 | BA13: =AS13/AV13 -> 0.75062752 | BB13: =AU13*BA13/(1-BA13) -> 458433 | BD13: =AX13/(SUM($AX13:$AZ13)) -> 0.36912673 | BE13: =AY13/(SUM($AX13:$AZ13)) -> 0.0038058391 | BF13: =AZ13/(SUM($AX13:$AZ13)) -> 0.62706743 | BP13: Grant | BQ13: 1959 | BR13: 651622 | BS13: 241353 | BT13: 5430 | BU13: 15632 | BV13: 0 | BW13: 0 | BX13: 236907 | BY13: 152300 | BZ13: =SUM(BS13:BY13) -> 651622 | CB13: 0.766 | CC13: =BQ13 -> 1959 | CD13: =(BR13-AV13)/AV13 -> 0.066950697 | CE13: =(BY13-AU13)/AU13 -> 0
A14: =N14 -> Grant | B14: =J14 -> 1960 | C14: =K14 -> 263700 | D14: =L14 -> 416907 | E14: =LN(D14/C14) -> 0.45805108 | F14: =A14 -> Grant | G14: =P14 -> 144782 | H14: =W14 -> 341713.55 | I14: =LN(H14/G14) -> 0.85874365 | J14: 1960 | K14: 263700 | L14: 416907 | N14: =BP14 -> Grant | O14: =BQ14 -> 1960 | P14: =BY14 -> 144782 | Q14: =BR14 -> 390714 | S14: =$Q17*S$2 -> 36508.696 | T14: =$Q18*T$2 -> 282123.34 | U14: =$Q19*U$2 -> 22474.354 | V14: =$Q20*V$2 -> 607.162 | W14: =SUM(S14:V14) -> 341713.55 | AB14: =W14 -> 341713.55 | AK14: Cass | AL14: 1960 | AM14: 146889 | AN14: N/A | AO14: 4618 | AP14: 21523 | AQ14: 185 | AR14: 77262 | AS14: 250476 | AT14: 0.49 | AU14: 263700 | AV14: 514176 | AW14: =AS14/AV14 -> 0.48714059 | AX14: =AM14/AV14 -> 0.28567844 | AY14: =AO14/(AV14-AM14) -> 0.012573274 | AZ14: =AR14/(AV14-AM14-AO14-AQ14) -> 0.21314596 | BA14: =AS14/AV14 -> 0.48714059 | BB14: =AU14*BA14/(1-BA14) -> 250476 | BD14: =AX14/(SUM($AX14:$AZ14)) -> 0.55862288 | BE14: =AY14/(SUM($AX14:$AZ14)) -> 0.024586099 | BF14: =AZ14/(SUM($AX14:$AZ14)) -> 0.41679102 | BP14: Grant | BQ14: 1960 | BR14: 390714 | BS14: 141635 | BT14: 1189 | BU14: 4310 | BV14: 21523 | BW14: 185 | BX14: 77090 | BY14: 144782 | BZ14: =SUM(BS14:BY14) -> 390714 | CB14: 0.629 | CC14: =BQ14 -> 1960 | CD14: =(BR14-AV14)/AV14 -> -0.24011622 | CE14: =(BY14-AU14)/AU14 -> -0.45095942
A15: =N15 -> Grant | B15: =J15 -> 1961 | C15: =K15 -> 172700 | D15: =L15 -> 288161 | E15: =LN(D15/C15) -> 0.51196337 | F15: =A15 -> Grant | G15: =P15 -> 103920 | H15: =W15 -> 225157.11 | I15: =LN(H15/G15) -> 0.77317706 | J15: 1961 | K15: 172700 | L15: 288161 | N15: =BP15 -> Grant | O15: =BQ15 -> 1961 | P15: =BY15 -> 103920 | Q15: =BR15 -> 253644 | S15: =$Q18*S$2 -> 39910.749 | T15: =$Q19*T$2 -> 129439.79 | U15: =$Q20*U$2 -> 55339.365 | V15: =$Q21*V$2 -> 467.20892 | W15: =SUM(S15:V15) -> 225157.11 | AB15: =W15 -> 225157.11 | AK15: Cass | AL15: 1961 | AM15: 65963 | AN15: N/A | AO15: 5894 | AP15: 15803 | AQ15: 20 | AR15: 57545 | AS15: 145224 | AT15: 0.46 | AU15: 172700 | AV15: 317924 | AW15: =AS15/AV15 -> 0.45678841 | AX15: =AM15/AV15 -> 0.2074804 | AY15: =AO15/(AV15-AM15) -> 0.023392509 | AZ15: =AR15/(AV15-AM15-AO15-AQ15) -> 0.23387808 | BA15: =AS15/AV15 -> 0.45678841 | BB15: =AU15*BA15/(1-BA15) -> 145224 | BD15: =AX15/(SUM($AX15:$AZ15)) -> 0.44643348 | BE15: =AY15/(SUM($AX15:$AZ15)) -> 0.050333425 | BF15: =AZ15/(SUM($AX15:$AZ15)) -> 0.50323309 | BP15: Grant | BQ15: 1961 | BR15: 253644 | BS15: 69640 | BT15: 1131 | BU15: 5676 | BV15: 15803 | BW15: 20 | BX15: 57454 | BY15: 103920 | BZ15: =SUM(BS15:BY15) -> 253644 | CB15: 0.59 | CC15: =BQ15 -> 1961 | CD15: =(BR15-AV15)/AV15 -> -0.20218669 | CE15: =(BY15-AU15)/AU15 -> -0.39826288
A16: =N16 -> Grant | B16: =J16 -> 1962 | C16: =K16 -> 180200 | D16: =L16 -> 423280 | E16: =LN(D16/C16) -> 0.85396655 | F16: =A16 -> Grant | G16: =P16 -> 130357 | H16: =W16 -> 381286.84 | I16: =LN(H16/G16) -> 1.0732751 | J16: 1962 | K16: 180200 | L16: 423280 | N16: =BP16 -> Grant | O16: =BQ16 -> 1962 | P16: =BY16 -> 130357 | Q16: =BR16 -> 249239 | S16: =$Q19*S$2 -> 18311.278 | T16: =$Q20*T$2 -> 318723.99 | U16: =$Q21*U$2 -> 42583.437 | V16: =$Q22*V$2 -> 1668.133 | W16: =SUM(S16:V16) -> 381286.84 | AB16: =W16 -> 381286.84 | AK16: Cass | AL16: 1962 | AM16: 36568 | AN16: N/A | AO16: 8034 | AP16: 8741 | AQ16: 33 | AR16: 58870 | AS16: 112245 | AT16: 0.38 | AU16: 180200 | AV16: 292445 | AW16: =AS16/AV16 -> 0.38381576 | AX16: =AM16/AV16 -> 0.12504232 | AY16: =AO16/(AV16-AM16) -> 0.031397898 | AZ16: =AR16/(AV16-AM16-AO16-AQ16) -> 0.23756103 | BA16: =AS16/AV16 -> 0.38381576 | BB16: =AU16*BA16/(1-BA16) -> 112245 | BD16: =AX16/(SUM($AX16:$AZ16)) -> 0.31736528 | BE16: =AY16/(SUM($AX16:$AZ16)) -> 0.079689844 | BF16: =AZ16/(SUM($AX16:$AZ16)) -> 0.60294488 | BP16: Grant | BQ16: 1962 | BR16: 249239 | BS16: 42750 | BT16: 1338 | BU16: 7155 | BV16: 8741 | BW16: 33 | BX16: 58866 | BY16: 130357 | BZ16: =SUM(BS16:BY16) -> 249240 | CB16: 0.477 | CC16: =BQ16 -> 1962 | CD16: =(BR16-AV16)/AV16 -> -0.1477406 | CE16: =(BY16-AU16)/AU16 -> -0.27659822
A17: =N17 -> Grant | B17: =J17 -> 1963 | C17: =K17 -> 214200 | D17: =L17 -> 430785 | E17: =LN(D17/C17) -> 0.69869897 | F17: =A17 -> Grant | G17: =P17 -> 192245 | H17: =W17 -> 443223.02 | I17: =LN(H17/G17) -> 0.83530247 | J17: 1963 | K17: 214200 | L17: 430785 | N17: =BP17 -> Grant | O17: =BQ17 -> 1963 | P17: =BY17 -> 192245 | Q17: =BR17 -> 339884 | S17: =$Q20*S$2 -> 45088.482 | T17: =$Q21*T$2 -> 245256.93 | U17: =$Q22*U$2 -> 152040.84 | V17: =$Q23*V$2 -> 836.7634 | W17: =SUM(S17:V17) -> 443223.02 | AB17: =W17 -> 443223.02 | AK17: Cass | AL17: 1963 | AM17: 75293 | AN17: N/A | AO17: 9163 | AP17: 9807 | AQ17: 360 | AR17: 64548 | AS17: 159172 | AT17: 0.43 | AU17: 214200 | AV17: 373372 | AW17: =AS17/AV17 -> 0.42630942 | AX17: =AM17/AV17 -> 0.20165679 | AY17: =AO17/(AV17-AM17) -> 0.030740173 | AZ17: =AR17/(AV17-AM17-AO17-AQ17) -> 0.22369315 | BA17: =AS17/AV17 -> 0.42630942 | BB17: =AU17*BA17/(1-BA17) -> 159172 | BD17: =AX17/(SUM($AX17:$AZ17)) -> 0.44214243 | BE17: =AY17/(SUM($AX17:$AZ17)) -> 0.067399341 | BF17: =AZ17/(SUM($AX17:$AZ17)) -> 0.49045823 | BP17: Grant | BQ17: 1963 | BR17: 339884 | BS17: 65476 | BT17: 0 | BU17: 7567 | BV17: 9807 | BW17: 360 | BX17: 64428 | BY17: 192245 | BZ17: =SUM(BS17:BY17) -> 339883 | CB17: 0.434 | CC17: =BQ17 -> 1963 | CD17: =(BR17-AV17)/AV17 -> -0.089690711 | CE17: =(BY17-AU17)/AU17 -> -0.10249767
A18: =N18 -> Grant | B18: =J18 -> 1964 | C18: =K18 -> 325400 | D18: =L18 -> 1165723 | E18: =LN(D18/C18) -> 1.2760416 | F18: =A18 -> Grant | G18: =P18 -> 246741 | H18: =W18 -> 987701.83 | I18: =LN(H18/G18) -> 1.3870417 | J18: 1964 | K18: 325400 | L18: 1165723 | N18: =BP18 -> Grant | O18: =BQ18 -> 1964 | P18: =BY18 -> 246741 | Q18: =BR18 -> 371556 | S18: =$Q21*S$2 -> 34695.421 | T18: =$Q22*T$2 -> 875670.74 | U18: =$Q23*U$2 -> 76266.228 | V18: =$Q24*V$2 -> 1069.4428 | W18: =SUM(S18:V18) -> 987701.83 | AB18: =W18 -> 987701.83 | AK18: Cass | AL18: 1964 | AM18: 27470 | AN18: N/A | AO18: 9025 | AP18: 11350 | AQ18: 437 | AR18: 73031 | AS18: 121313 | AT18: 0.27 | AU18: 325400 | AV18: 446713 | AW18: =AS18/AV18 -> 0.2715681 | AX18: =AM18/AV18 -> 0.061493621 | AY18: =AO18/(AV18-AM18) -> 0.021526895 | AZ18: =AR18/(AV18-AM18-AO18-AQ18) -> 0.17821959 | BA18: =AS18/AV18 -> 0.2715681 | BB18: =AU18*BA18/(1-BA18) -> 121313 | BD18: =AX18/(SUM($AX18:$AZ18)) -> 0.2353912 | BE18: =AY18/(SUM($AX18:$AZ18)) -> 0.08240272 | BF18: =AZ18/(SUM($AX18:$AZ18)) -> 0.68220608 | BP18: Grant | BQ18: 1964 | BR18: 371556 | BS18: 31979 | BT18: 0 | BU18: 8372 | BV18: 11350 | BW18: 437 | BX18: 72677 | BY18: 246741 | BZ18: =SUM(BS18:BY18) -> 371556 | CB18: 0.336 | CC18: =BQ18 -> 1964 | CD18: =(BR18-AV18)/AV18 -> -0.16824449 | CE18: =(BY18-AU18)/AU18 -> -0.24173018
... A29: =N29 -> Grant | B29: =J29 -> 1975 | C29: =K29 -> 191445 | D29: =L29 -> 527760 | E29: =LN(D29/C29) -> 1.0140411 | F29: =A29 -> Grant | G29: =P29 -> 191420 | H29: =W29 -> 482340.97 | I29: =LN(H29/G29) -> 0.92418131 | J29: 1975 | K29: 191445 | L29: 527760 | N29: =BP29 -> Grant | O29: =BQ29 -> 1975 | P29: =BY29 -> 191420 | Q29: =BR29 -> 486199 | S29: =$Q32*S$2 -> 127310.92 | T29: =$Q33*T$2 -> 234420.93 | U29: =$Q34*U$2 -> 119885.5 | V29: =$Q35*V$2 -> 723.61889 | W29: =SUM(S29:V29) -> 482340.97 | AB29: =W29 -> 482340.97 | AK29: Cass | AL29: 1975 | AM29: 144527 | AN29: N/A | AO29: 17876 | AP29: 69307 | AQ29: 262 | AR29: 80560 | AS29: 312533 | AT29: 0.62 | AU29: 191445 | AV29: 503978 | AW29: =AS29/AV29 -> 0.62013223 | AX29: =AM29/AV29 -> 0.28677244 | AY29: =AO29/(AV29-AM29) -> 0.049731396 | AZ29: =AR29/(AV29-AM29-AO29-AQ29) -> 0.23602969 | BA29: =AS29/AV29 -> 0.62013223 | BB29: =AU29*BA29/(1-BA29) -> 312533 | BD29: =AX29/(SUM($AX29:$AZ29)) -> 0.50088323 | BE29: =AY29/(SUM($AX29:$AZ29)) -> 0.086861981 | BF29: =AZ29/(SUM($AX29:$AZ29)) -> 0.41225479 | BP29: Grant | BQ29: 1975 | BR29: 486199 | BS29: 124247 | BT29: 3950 | BU29: 16433 | BV29: 69307 | BW29: 0 | BX29: 80842 | BY29: 191420 | BZ29: =SUM(BS29:BY29) -> 486199 | CB29: 0.606 | CC29: =BQ29 -> 1975 | CD29: =(BR29-AV29)/AV29 -> -0.035277334 | CE29: =(BY29-AU29)/AU29 -> -0.00013058581
A30: =N30 -> Grant | B30: =J30 -> 1976 | C30: =K30 -> 340467 | D30: =L30 -> 761292 | E30: =LN(D30/C30) -> 0.80469879 | F30: =A30 -> Grant | G30: =P30 -> 340517 | H30: =W30 -> 790637.36 | I30: =LN(H30/G30) -> 0.84237435 | J30: 1976 | K30: 340467 | L30: 761292 | N30: =BP30 -> Grant | O30: =BQ30 -> 1976 | P30: =BY30 -> 340517 | Q30: =BR30 -> 1003722 | S30: =$Q33*S$2 -> 33162.499 | T30: =$Q34*T$2 -> 690473.86 | U30: =$Q35*U$2 -> 65953.749 | V30: =$Q36*V$2 -> 1047.2485 | W30: =SUM(S30:V30) -> 790637.36 | AB30: =W30 -> 790637.36 | AG30: Approx. | AH30: Approx. | AI30: Approx. | AK30: Cass | AL30: 1976 | AM30: 343629 | AN30: N/A | AO30: 49645 | AP30: 191507 | AQ30: 1126 | AR30: 187661 | AS30: 773568 | AT30: 0.69 | AU30: 340467 | AV30: 1114035 | AW30: =AS30/AV30 -> 0.69438393 | AX30: =AM30/AV30 -> 0.3084544 | AY30: =AO30/(AV30-AM30) -> 0.064440048 | AZ30: =AR30/(AV30-AM30-AO30-AQ30) -> 0.26077247 | BA30: =AS30/AV30 -> 0.69438393 | BB30: =AU30*BA30/(1-BA30) -> 773568 | BD30: =AX30/(SUM($AX30:$AZ30)) -> 0.48677687 | BE30: =AY30/(SUM($AX30:$AZ30)) -> 0.10169388 | BF30: =AZ30/(SUM($AX30:$AZ30)) -> 0.41152925 | BP30: Grant | BQ30: 1976 | BR30: 1003722 | BS30: 237524 | BT30: 4559 | BU30: 43244 | BV30: 191507 | BW30: 0 | BX30: 186371 | BY30: 340517 | BZ30: =SUM(BS30:BY30) -> 1003722 | CB30: 0.661 | CC30: =BQ30 -> 1976 | CD30: =(BR30-AV30)/AV30 -> -0.099021126 | CE30: =(BY30-AU30)/AU30 -> 0.00014685711
A31: =N31 -> Grant | B31: =J31 -> 1977 | C31: =K31 -> 599371 | D31: =L31 -> 583647 | E31: =LN(D31/C31) -> -0.026584424 | F31: =A31 -> Grant | G31: =P31 -> 599341 | H31: =W31 -> 573665.97 | I31: =LN(H31/G31) -> -0.04378343 | J31: 1977 | K31: 599371 | L31: 583647 | N31: =BP31 -> Grant | O31: =BQ31 -> 1977 | P31: =BY31 -> 599341 | Q31: =BR31 -> 722536 | S31: =$Q34*S$2 -> 97678.303 | T31: =$Q35*T$2 -> 379856.94 | U31: =$Q36*U$2 -> 95450.745 | V31: =$Q37*V$2 -> 679.97938 | W31: =SUM(S31:V31) -> 573665.97 | AB31: =W31 -> 573665.97 | AD31: Source | AF31: Fraser R | AG31: Fraser R | AH31: Total HR | AI31: total return | AJ31: %dif with Grant | AK31: Cass | AL31: 1977 | AM31: 42066 | AN31: N/A | AO31: 8228 | AP31: 38846 | AQ31: 626 | AR31: 23728 | AS31: 113494 | AT31: 0.16 | AU31: 599371 | AV31: 712865 | AW31: =AS31/AV31 -> 0.15920827 | AX31: =AM31/AV31 -> 0.05900977 | AY31: =AO31/(AV31-AM31) -> 0.012265969 | AZ31: =AR31/(AV31-AM31-AO31-AQ31) -> 0.035845878 | BA31: =AS31/AV31 -> 0.15920827 | BB31: =AU31*BA31/(1-BA31) -> 113494 | BD31: =AX31/(SUM($AX31:$AZ31)) -> 0.55086706 | BE31: =AY31/(SUM($AX31:$AZ31)) -> 0.11450508 | BF31: =AZ31/(SUM($AX31:$AZ31)) -> 0.33462787 | BP31: Grant | BQ31: 1977 | BR31: 722536 | BS31: 54997 | BT31: 0 | BU31: 6358 | BV31: 36660 | BW31: 0 | BX31: 25180 | BY31: 599341 | BZ31: =SUM(BS31:BY31) -> 722536 | CB31: 0.171 | CC31: =BQ31 -> 1977 | CD31: =(BR31-AV31)/AV31 -> 0.013566384 | CE31: =(BY31-AU31)/AU31 -> -5.0052472e-05
A32: =N32 -> Grant | B32: =J32 -> 1978 | C32: =K32 -> 359065 | D32: =L32 -> 635560 | E32: =LN(D32/C32) -> 0.57100307 | F32: =A32 -> Grant | G32: =P32 -> 358990 | H32: =W32 -> 666342.58 | I32: =LN(H32/G32) -> 0.6185094 | J32: 1978 | K32: 359065 | L32: 635560 | N32: =BP32 -> Grant | O32: =BQ32 -> 1978 | P32: =BY32 -> 358990 | Q32: =BR32 -> 1185223 | S32: =$Q35*S$2 -> 53736.692 | T32: =$Q36*T$2 -> 549743.25 | U32: =$Q37*U$2 -> 61976.255 | V32: =$Q38*V$2 -> 886.39123 | W32: =SUM(S32:V32) -> 666342.58 | AB32: =W32 -> 666342.58 | AE32: broodyear | AF32: spawners | AG32: total catch | AH32: HR | AK32: Cass | AL32: 1978 | AM32: 485439 | AN32: N/A | AO32: 12318 | AP32: 295733 | AQ32: 277 | AR32: 134260 | AS32: 928027 | AT32: 0.72 | AU32: 359065 | AV32: 1287092 | AW32: =AS32/AV32 -> 0.72102616 | AX32: =AM32/AV32 -> 0.37715952 | AY32: =AO32/(AV32-AM32) -> 0.015365751 | AZ32: =AR32/(AV32-AM32-AO32-AQ32) -> 0.17015226 | BA32: =AS32/AV32 -> 0.72102616 | BB32: =AU32*BA32/(1-BA32) -> 928027 | BD32: =AX32/(SUM($AX32:$AZ32)) -> 0.67029426 | BE32: =AY32/(SUM($AX32:$AZ32)) -> 0.027308271 | BF32: =AZ32/(SUM($AX32:$AZ32)) -> 0.30239746 | BP32: Grant | BQ32: 1978 | BR32: 1185223 | BS32: 405890 | BT32: 729 | BU32: 11113 | BV32: 273516 | BW32: 0 | BX32: 134985 | BY32: 358990 | BZ32: =SUM(BS32:BY32) -> 1185223 | CB32: 0.697 | CC32: =BQ32 -> 1978 | CD32: =(BR32-AV32)/AV32 -> -0.079146634 | CE32: =(BY32-AU32)/AU32 -> -0.00020887583 | CH32: broodyear | CI32: spawners | CJ32: recruits | CK32: %dif Spa | CL32: %dif Rec
A33: =N33 -> Grant | B33: =J33 -> 1979 | C33: =K33 -> 255634 | D33: =L33 -> 510199 | E33: =LN(D33/C33) -> 0.69105411 | F33: =A33 -> Grant | G33: =P33 -> 255634 | H33: =W33 -> 518168.16 | I33: =LN(H33/G33) -> 0.7065531 | J33: 1979 | K33: 255634 | L33: 510199 | N33: =BP33 -> Grant | O33: =BQ33 -> 1979 | P33: =BY33 -> 255634 | Q33: =BR33 -> 308732 | S33: =$Q36*S$2 -> 77769.761 | T33: =$Q37*T$2 -> 356948.79 | U33: =$Q38*U$2 -> 80789.522 | V33: =$Q39*V$2 -> 2660.0922 | W33: =SUM(S33:V33) -> 518168.16 | AB33: =W33 -> 518168.16 | AD33: Cass | AE33: 1979 | AF33: 255634 | AG33: =AS33 -> 42262 | AH33: =AG33/(AF33+AG33) -> 0.1418683 | AI33: =AF33+AG33 -> 297896 | AJ33: =(AI33-BR33)/BR33 -> -0.035098402 | AK33: Cass | AL33: 1979 | AM33: 20326 | AN33: N/A | AO33: 2105 | AP33: 3455 | AQ33: 403 | AR33: 15973 | AS33: 42262 | AT33: 0.14 | AU33: 255634 | AV33: 297896 | AW33: =AS33/AV33 -> 0.1418683 | AX33: =AM33/AV33 -> 0.068231866 | AY33: =AO33/(AV33-AM33) -> 0.0075836726 | AZ33: =AR33/(AV33-AM33-AO33-AQ33) -> 0.058070544 | BA33: =AS33/AV33 -> 0.1418683 | BB33: =AU33*BA33/(1-BA33) -> 42262 | BC33: Harvest Rate | BD33: =AX33/(SUM($AX33:$AZ33)) -> 0.50962628 | BE33: =AY33/(SUM($AX33:$AZ33)) -> 0.056642725 | BF33: =AZ33/(SUM($AX33:$AZ33)) -> 0.433731 | BH33: Year | BI33: Spawners | BJ33: Harvest | BK33: Harvest Rate d2 | BL33: Returns | BN33: Harvest Rate d1 | BP33: Grant | BQ33: 1979 | BR33: 308732 | BS33: 31093 | BT33: 0 | BU33: 1381 | BV33: 3321 | BW33: 0 | BX33: 17304 | BY33: 255634 | BZ33: =SUM(BS33:BY33) -> 308733 | CB33: 0.172 | CC33: =BQ33 -> 1979 | CD33: =(BR33-AV33)/AV33 -> 0.036375111 | CE33: =(BY33-AU33)/AU33 -> 0 | CH33: 1979 | CI33: 255634 | CJ33: 510199 | CK33: =(CI33-P33)/P33 -> 0 | CL33: =(CJ33-AB33)/AB33 -> -0.015379494
A34: =N34 -> Grant | B34: =J34 -> 1980 | C34: =K34 -> 312182 | D34: =L34 -> 655505 | E34: =LN(D34/C34) -> 0.74181958 | F34: =A34 -> Grant | G34: =P34 -> 314011 | H34: =W34 -> 760537.66 | I34: =LN(H34/G34) -> 0.88459762 | J34: 1980 | K34: 312182 | L34: 655505 | N34: =BP34 -> Grant | O34: =BQ34 -> 1980 | P34: =BY34 -> 314011 | Q34: =BR34 -> 909353 | S34: =$Q37*S$2 -> 50495.977 | T34: =$Q38*T$2 -> 465302.75 | U34: =$Q39*U$2 -> 242452.28 | V34: =$Q40*V$2 -> 2286.6525 | W34: =SUM(S34:V34) -> 760537.66 | AB34: =W34 -> 760537.66 | AD34: Cass | AE34: 1980 | AF34: 312182 | AG34: =AS34 -> 594711 | AH34: =AG34/(AF34+AG34) -> 0.65576755 | AI34: =AF34+AG34 -> 906893 | AJ34: =(AI34-BR34)/BR34 -> -0.0027052201 | AK34: Cass | AL34: 1980 | AM34: 243146 | AN34: N/A | AO34: 13550 | AP34: 245019 | AQ34: 3666 | AR34: 89330 | AS34: 594711 | AT34: =AS34/AV34 -> 0.65576755 | AU34: 312182 | AV34: 906893 | AW34: =AS34/AV34 -> 0.65576755 | AX34: =AM34/AV34 -> 0.26810881 | AY34: =AO34/(AV34-AM34) -> 0.020414405 | AZ34: =AR34/(AV34-AM34-AO34-AQ34) -> 0.13816816 | BA34: =AS34/AV34 -> 0.65576755 | BB34: =AU34*BA34/(1-BA34) -> 594711 | BC34: 0.51937603 | BD34: =AX34/(SUM($AX34:$AZ34)) -> 0.62834363 | BE34: =AY34/(SUM($AX34:$AZ34)) -> 0.047843491 | BF34: =AZ34/(SUM($AX34:$AZ34)) -> 0.32381288 | BH34: 1980 | BI34: 1373377 | BJ34: 1162099.8 | BK34: 0.45833581 | BL34: 2535476.8 | BN34: =AT34 -> 0.65576755 | BP34: Grant | BQ34: 1980 | BR34: 909353 | BS34: 242556 | BT34: 8546 | BU34: 12026 | BV34: 241835 | BW34: 0 | BX34: 90380 | BY34: 314011 | BZ34: =SUM(BS34:BY34) -> 909354 | CB34: 0.655 | CC34: =BQ34 -> 1980 | CD34: =(BR34-AV34)/AV34 -> 0.0027125582 | CE34: =(BY34-AU34)/AU34 -> 0.0058587619 | CH34: 1980 | CI34: 312182 | CJ34: 655505 | CK34: =(CI34-P34)/P34 -> -0.0058246367 | CL34: =(CJ34-AB34)/AB34 -> -0.13810317
A35: =N35 -> Grant | B35: =J35 -> 1981 | C35: =K35 -> 435345 | D35: =L35 -> 1492293 | E35: =LN(D35/C35) -> 1.2319303 | F35: =A35 -> Grant | G35: =P35 -> 436996 | H35: =W35 -> 1671326 | I35: =LN(H35/G35) -> 1.3414485 | J35: 1981 | K35: 435345 | L35: 1492293 | N35: =BP35 -> Grant | O35: =BQ35 -> 1981 | P35: =BY35 -> 436996 | Q35: =BR35 -> 500271 | S35: =$Q38*S$2 -> 65824.336 | T35: =$Q39*T$2 -> 1396390.4 | U35: =$Q40*U$2 -> 208415.38 | V35: =$Q41*V$2 -> 695.85421 | W35: =SUM(S35:V35) -> 1671326 | AB35: =W35 -> 1671326 | AD35: Cass | AE35: 1981 | AF35: 435345 | AG35: =AS35 -> 56270 | AH35: =AG35/(AF35+AG35) -> 0.11445949 | AI35: =AF35+AG35 -> 491615 | AJ35: =(AI35-BR35)/BR35 -> -0.017302622 | AK35: Cass | AL35: 1981 | AM35: 26519 | AN35: N/A | AO35: 3205 | AP35: 5814 | AQ35: 771 | AR35: 19961 | AS35: 56270 | AT35: =AS35/AV35 -> 0.11445949 | AU35: 435345 | AV35: 491615 | AW35: =AS35/AV35 -> 0.11445949 | AX35: =AM35/AV35 -> 0.053942618 | AY35: =AO35/(AV35-AM35) -> 0.0068910504 | AZ35: =AR35/(AV35-AM35-AO35-AQ35) -> 0.043288081 | BA35: =AS35/AV35 -> 0.11445949 | BB35: =AU35*BA35/(1-BA35) -> 56270 | BC35: 0.1414136 | BD35: =AX35/(SUM($AX35:$AZ35)) -> 0.51807253 | BE35: =AY35/(SUM($AX35:$AZ35)) -> 0.066182623 | BF35: =AZ35/(SUM($AX35:$AZ35)) -> 0.41574485 | BH35: 1981 | BI35: 1302540 | BJ35: 185726.45 | BK35: 0.12479381 | BL35: 1488266.4 | BN35: =AT35 -> 0.11445949 | BP35: Grant | BQ35: 1981 | BR35: 500271 | BS35: 30394 | BT35: 3370 | BU35: 2288 | BV35: 5814 | BW35: 0 | BX35: 21408 | BY35: 436996 | BZ35: =SUM(BS35:BY35) -> 500270 | CB35: 0.126 | CC35: =BQ35 -> 1981 | CD35: =(BR35-AV35)/AV35 -> 0.017607274 | CE35: =(BY35-AU35)/AU35 -> 0.0037923945 | CH35: 1981 | CI35: 435345 | CJ35: 1492293 | CK35: =(CI35-P35)/P35 -> -0.0037780666 | CL35: =(CJ35-AB35)/AB35 -> -0.10712032
A36: =N36 -> Grant | B36: =J36 -> 1982 | C36: =K36 -> 322286 | D36: =L36 -> 1416221 | E36: =LN(D36/C36) -> 1.480308 | F36: =A36 -> Grant | G36: =P36 -> 326439 | H36: =W36 -> 1462818.4 | I36: =LN(H36/G36) -> 1.4998772 | J36: 1982 | K36: 322286 | L36: 1416221 | N36: =BP36 -> Grant | O36: =BQ36 -> 1982 | P36: =BY36 -> 326439 | Q36: =BR36 -> 724011 | S36: =$Q39*S$2 -> 197541.22 | T36: =$Q40*T$2 -> 1200356.8 | U36: =$Q41*U$2 -> 63423.156 | V36: =$Q42*V$2 -> 1497.2402 | W36: =SUM(S36:V36) -> 1462818.4 | AB36: =W36 -> 1462818.4 | AD36: Cass | AE36: 1982 | AF36: 322286 | AG36: =AS36 -> 383164 | AH36: =AG36/(AF36+AG36) -> 0.54314835 | AI36: =AF36+AG36 -> 705450 | AJ36: =(AI36-BR36)/BR36 -> -0.025636351 | AK36: Cass | AL36: 1982 | AM36: 235914 | AN36: N/A | AO36: 8527 | AP36: 54570 | AQ36: 1649 | AR36: 82505 | AS36: 383164 | AT36: =AS36/AV36 -> 0.54314835 | AU36: 322286 | AV36: 705450 | AW36: =AS36/AV36 -> 0.54314835 | AX36: =AM36/AV36 -> 0.33441633 | AY36: =AO36/(AV36-AM36) -> 0.018160482 | AZ36: =AR36/(AV36-AM36-AO36-AQ36) -> 0.17960859 | BA36: =AS36/AV36 -> 0.54314835 | BB36: =AU36*BA36/(1-BA36) -> 383164 | BC36: 0.57254889 | BD36: =AX36/(SUM($AX36:$AZ36)) -> 0.62838314 | BE36: =AY36/(SUM($AX36:$AZ36)) -> 0.034124352 | BF36: =AZ36/(SUM($AX36:$AZ36)) -> 0.33749251 | BH36: 1982 | BI36: 1453419 | BJ36: 1484320.9 | BK36: 0.50525946 | BL36: 2937739.9 | BN36: =AT36 -> 0.54314835 | BP36: Grant | BQ36: 1982 | BR36: 724011 | BS36: 240409 | BT36: 12660 | BU36: 7095 | BV36: 54508 | BW36: 0 | BX36: 82899 | BY36: 326439 | BZ36: =SUM(BS36:BY36) -> 724010 | CB36: 0.549 | CC36: =BQ36 -> 1982 | CD36: =(BR36-AV36)/AV36 -> 0.026310865 | CE36: =(BY36-AU36)/AU36 -> 0.01288607 | CH36: 1982 | CI36: 322286 | CJ36: 1416221 | CK36: =(CI36-P36)/P36 -> -0.012722132 | CL36: =(CJ36-AB36)/AB36 -> -0.031854522
A37: =N37 -> Grant | B37: =J37 -> 1983 | C37: =K37 -> 367363 | D37: =L37 -> 795564 | E37: =LN(D37/C37) -> 0.77270084 | F37: =A37 -> Grant | G37: =P37 -> 371770 | H37: =W37 -> 673139.64 | I37: =LN(H37/G37) -> 0.59367742 | J37: 1983 | K37: 367363 | L37: 795564 | N37: =BP37 -> Grant | O37: =BQ37 -> 1983 | P37: =BY37 -> 371770 | Q37: =BR37 -> 470101 | S37: =$Q40*S$2 -> 169809.2 | T37: =$Q41*T$2 -> 365282.13 | U37: =$Q42*U$2 -> 136464.94 | V37: =$Q43*V$2 -> 1583.3766 | W37: =SUM(S37:V37) -> 673139.64 | AB37: =W37 -> 673139.64 | AD37: Cass | AE37: 1983 | AF37: 367363 | AG37: =AS37 -> 88034 | AH37: =AG37/(AF37+AG37) -> 0.19331265 | AI37: =AF37+AG37 -> 455397 | AJ37: =(AI37-BR37)/BR37 -> -0.031278385 | AK37: Cass | AL37: 1983 | AM37: 56191 | AN37: N/A | AO37: 81 | AP37: 1671 | AQ37: 4899 | AR37: 25194 | AS37: 88034 | AT37: =AS37/AV37 -> 0.19331265 | AU37: 367363 | AV37: 455397 | AW37: =AS37/AV37 -> 0.19331265 | AX37: =AM37/AV37 -> 0.12338904 | AY37: =AO37/(AV37-AM37) -> 0.00020290276 | AZ37: =AR37/(AV37-AM37-AO37-AQ37) -> 0.063907505 | BA37: =AS37/AV37 -> 0.19331265 | BB37: =AU37*BA37/(1-BA37) -> 88034 | BC37: 0.23086634 | BD37: =AX37/(SUM($AX37:$AZ37)) -> 0.65807682 | BE37: =AY37/(SUM($AX37:$AZ37)) -> 0.0010821512 | BF37: =AZ37/(SUM($AX37:$AZ37)) -> 0.34084102 | BH37: 1983 | BI37: 1196968 | BJ37: 306257.42 | BK37: 0.20373353 | BL37: 1503225.4 | BN37: =AT37 -> 0.19331265 | BP37: Grant | BQ37: 1983 | BR37: 470101 | BS37: 60431 | BT37: 14683 | BU37: 20 | BV37: 1602 | BW37: 0 | BX37: 21595 | BY37: 371770 | BZ37: =SUM(BS37:BY37) -> 470101 | CB37: 0.209 | CC37: =BQ37 -> 1983 | CD37: =(BR37-AV37)/AV37 -> 0.032288311 | CE37: =(BY37-AU37)/AU37 -> 0.011996309 | CH37: 1983 | CI37: 367363 | CJ37: 795564 | CK37: =(CI37-P37)/P37 -> -0.011854103 | CL37: =(CJ37-AB37)/AB37 -> 0.18187067
A38: =N38 -> Grant | B38: =J38 -> 1984 | C38: =K38 -> 540265 | D38: =L38 -> 1061099 | E38: =LN(D38/C38) -> 0.67500068 | F38: =A38 -> Grant | G38: =P38 -> 541478 | H38: =W38 -> 984259.76 | I38: =LN(H38/G38) -> 0.59758741 | J38: 1984 | K38: 540265 | L38: 1061099 | N38: =BP38 -> Grant | O38: =BQ38 -> 1984 | P38: =BY38 -> 541478 | Q38: =BR38 -> 612803 | S38: =$Q41*S$2 -> 51674.858 | T38: =$Q42*T$2 -> 785962.2 | U38: =$Q43*U$2 -> 144315.77 | V38: =$Q44*V$2 -> 2306.9275 | W38: =SUM(S38:V38) -> 984259.76 | AB38: =W38 -> 984259.76 | AD38: Cass | AE38: 1984 | AF38: 540265 | AG38: =AS38 -> 65644 | AH38: =AG38/(AF38+AG38) -> 0.1083397 | AI38: =AF38+AG38 -> 605909 | AJ38: =(AI38-BR38)/BR38 -> -0.011249945 | AK38: Cass | AL38: 1984 | AM38: 19746 | AN38: N/A | AO38: 6131 | AP38: 1192 | AQ38: 4846 | AR38: 337299 | AS38: 65644 | AT38: =AS38/AV38 -> 0.1083397 | AU38: 540265 | AV38: 605909 | AW38: =AS38/AV38 -> 0.1083397 | AX38: =AM38/AV38 -> 0.032589052 | AY38: =AO38/(AV38-AM38) -> 0.010459548 | AZ38: =AR38/(AV38-AM38-AO38-AQ38) -> 0.58641726 | BA38: =AS38/AV38 -> 0.1083397 | BB38: =AU38*BA38/(1-BA38) -> 65644 | BC38: 0.1743125 | BD38: =AX38/(SUM($AX38:$AZ38)) -> 0.051772549 | BE38: =AY38/(SUM($AX38:$AZ38)) -> 0.016616545 | BF38: =AZ38/(SUM($AX38:$AZ38)) -> 0.93161091 | BH38: 1984 | BI38: 1627518 | BJ38: 295867.09 | BK38: 0.15382624 | BL38: 1923385.1 | BN38: =AT38 -> 0.1083397 | BP38: Grant | BQ38: 1984 | BR38: 612803 | BS38: 30552 | BT38: 17335 | BU38: 1 | BV38: 1192 | BW38: 0 | BX38: 22246 | BY38: 541478 | BZ38: =SUM(BS38:BY38) -> 612804 | CB38: 0.116 | CC38: =BQ38 -> 1984 | CD38: =(BR38-AV38)/AV38 -> 0.011377946 | CE38: =(BY38-AU38)/AU38 -> 0.0022451945 | CH38: 1984 | CI38: 540265 | CJ38: 1061099 | CK38: =(CI38-P38)/P38 -> -0.0022401649 | CL38: =(CJ38-AB38)/AB38 -> 0.078068047
A39: =N39 -> Grant | B39: =J39 -> 1985 | C39: =K39 -> 1147702 | D39: =L39 -> 1010518 | E39: =LN(D39/C39) -> -0.12729861 | F39: =A39 -> Grant | G39: =P39 -> 1383808 | H39: =W39 -> 1154732 | I39: =LN(H39/G39) -> -0.18097084 | J39: 1985 | K39: 1147702 | L39: 1010518 | N39: =BP39 -> Grant | O39: =BQ39 -> 1985 | P39: =BY39 -> 1383808 | Q39: =BR39 -> 1839044 | S39: =$Q42*S$2 -> 111186.62 | T39: =$Q43*T$2 -> 831178.66 | U39: =$Q44*U$2 -> 210263.33 | V39: =$Q45*V$2 -> 2103.3883 | W39: =SUM(S39:V39) -> 1154732 | AB39: =W39 -> 1154732 | AD39: Cass | AE39: 1985 | AF39: 1147702 | AG39: =AS39 -> 604708 | AH39: =AG39/(AF39+AG39) -> 0.34507221 | AI39: =AF39+AG39 -> 1752410 | AJ39: =(AI39-BR39)/BR39 -> -0.047108171 | AK39: Cass | AL39: 1985 | AM39: 242114 | AN39: 36552 | AO39: 128032 | AP39: 124160 | AQ39: 15449 | AR39: 58400 | AS39: 604708 | AT39: =AS39/AV39 -> 0.34507221 | AU39: 1147702 | AV39: 1752410 | AW39: =AS39/AV39 -> 0.34507221 | AX39: =AM39/AV39 -> 0.13816059 | AY39: =AO39/(AV39-AM39) -> 0.084772786 | AZ39: =AR39/(AV39-AM39-AO39-AQ39) -> 0.04272707 | BA39: =AS39/AV39 -> 0.34507221 | BB39: =AU39*BA39/(1-BA39) -> 604708 | BC39: 0.38 | BD39: =AX39/(SUM($AX39:$AZ39)) -> 0.52006459 | BE39: =AY39/(SUM($AX39:$AZ39)) -> 0.31910202 | BF39: =AZ39/(SUM($AX39:$AZ39)) -> 0.16083339 | BH39: 1985 | BI39: 2969439 | BJ39: 1733316.5 | BK39: 0.36857466 | BL39: 4702755.5 | BN39: =AT39 -> 0.34507221 | BP39: Grant | BQ39: 1985 | BR39: 1839044 | BS39: 248099 | BT39: 23242 | BU39: 2142 | BV39: 124098 | BW39: 0 | BX39: 57656 | BY39: 1383808 | BZ39: =SUM(BS39:BY39) -> 1839045 | CB39: 0.248 | CC39: =BQ39 -> 1985 | CD39: =(BR39-AV39)/AV39 -> 0.049437061 | CE39: =(BY39-AU39)/AU39 -> 0.20572065 | CH39: 1985 | CI39: 1147702 | CJ39: 1010518 | CK39: =(CI39-P39)/P39 -> -0.17062049 | CL39: =(CJ39-AB39)/AB39 -> -0.12488958
A40: =N40 -> Grant | B40: =J40 -> 1986 | C40: =K40 -> 833591 | D40: =L40 -> 1322564 | E40: =LN(D40/C40) -> 0.46158468 | F40: =A40 -> Grant | G40: =P40 -> 997327 | H40: =W40 -> 1522545.3 | I40: =LN(H40/G40) -> 0.42306003 | J40: 1986 | K40: 833591 | L40: 1322564 | N40: =BP40 -> Grant | O40: =BQ40 -> 1986 | P40: =BY40 -> 997327 | Q40: =BR40 -> 1580868 | S40: =$Q43*S$2 -> 117583.19 | T40: =$Q44*T$2 -> 1210999.9 | U40: =$Q45*U$2 -> 191711.89 | V40: =$Q46*V$2 -> 2250.2742 | W40: =SUM(S40:V40) -> 1522545.3 | AB40: =W40 -> 1522545.3 | AD40: Cass | AE40: 1986 | AF40: 833591 | AG40: =AS40 -> 622194 | AH40: =AG40/(AF40+AG40) -> 0.42739416 | AI40: =AF40+AG40 -> 1455785 | AJ40: =(AI40-BR40)/BR40 -> -0.079122988 | AK40: Cass | AL40: 1986 | AM40: 342548 | AN40: 61331 | AO40: 17228 | AP40: 68213 | AQ40: 17213 | AR40: 115661 | AS40: 622194 | AT40: =AS40/AV40 -> 0.42739416 | AU40: 833591 | AV40: 1455785 | AW40: =AS40/AV40 -> 0.42739416 | AX40: =AM40/AV40 -> 0.23530123 | AY40: =AO40/(AV40-AM40) -> 0.015475591 | AZ40: =AR40/(AV40-AM40-AO40-AQ40) -> 0.10721304 | BA40: =AS40/AV40 -> 0.42739416 | BB40: =AU40*BA40/(1-BA40) -> 622194 | BC40: 0.5 | BD40: =AX40/(SUM($AX40:$AZ40)) -> 0.65728462 | BE40: =AY40/(SUM($AX40:$AZ40)) -> 0.043229131 | BF40: =AZ40/(SUM($AX40:$AZ40)) -> 0.29948625 | BH40: 1986 | BI40: 2321907 | BJ40: 1888703.2 | BK40: 0.44855808 | BL40: 4210610.2 | BN40: =AT40 -> 0.42739416 | BP40: Grant | BQ40: 1986 | BR40: 1580868 | BS40: 346413 | BT40: 54696 | BU40: 1188 | BV40: 67221 | BW40: 0 | BX40: 114023 | BY40: 997327 | BZ40: =SUM(BS40:BY40) -> 1580868 | CB40: 0.369 | CC40: =BQ40 -> 1986 | CD40: =(BR40-AV40)/AV40 -> 0.085921341 | CE40: =(BY40-AU40)/AU40 -> 0.19642247 | CH40: 1986 | CI40: 833591 | CJ40: 1322564 | CK40: =(CI40-P40)/P40 -> -0.16417484 | CL40: =(CJ40-AB40)/AB40 -> -0.13134668
A41: =N41 -> Grant | B41: =J41 -> 1987 | C41: =K41 -> 430000 | D41: =L41 -> 1116839 | E41: =LN(D41/C41) -> 0.95447244 | F41: =A41 -> Grant | G41: =P41 -> 363671 | H41: =W41 -> 1482704.4 | I41: =LN(H41/G41) -> 1.4053734 | J41: 1987 | K41: 430000 | L41: 1116839 | N41: =BP41 -> Grant | O41: =BQ41 -> 1987 | P41: =BY41 -> 363671 | Q41: =BR41 -> 481076 | S41: =$Q44*S$2 -> 171314.84 | T41: =$Q45*T$2 -> 1104153.9 | U41: =$Q46*U$2 -> 205099.7 | V41: =$Q47*V$2 -> 2135.9248 | W41: =SUM(S41:V41) -> 1482704.4 | AB41: =W41 -> 1482704.4 | AD41: Cass | AE41: 1987 | AF41: 430000 | AG41: =AS41 -> 136674 | AH41: =AG41/(AF41+AG41) -> 0.24118629 | AI41: =AF41+AG41 -> 566674 | AJ41: =(AI41-BR41)/BR41 -> 0.17793031 | AK41: Cass | AL41: 1987 | AM41: 17868 | AN41: 26729 | AO41: 22999 | AP41: 18649 | AQ41: 14081 | AR41: 36348 | AS41: 136674 | AT41: =AS41/AV41 -> 0.24118629 | AU41: 430000 | AV41: 566674 | AW41: =AS41/AV41 -> 0.24118629 | AX41: =AM41/AV41 -> 0.031531357 | AY41: =AO41/(AV41-AM41) -> 0.041907341 | AZ41: =AR41/(AV41-AM41-AO41-AQ41) -> 0.0710302 | BA41: =AS41/AV41 -> 0.24118629 | BB41: =AU41*BA41/(1-BA41) -> 136674 | BC41: 0.52 | BD41: =AX41/(SUM($AX41:$AZ41)) -> 0.21825706 | BE41: =AY41/(SUM($AX41:$AZ41)) -> 0.29007864 | BF41: =AZ41/(SUM($AX41:$AZ41)) -> 0.4916643 | BH41: 1987 | BI41: 1317145 | BJ41: 638770.32 | BK41: 0.32658383 | BL41: 1955915.3 | BN41: =AT41 -> 0.24118629 | BP41: Grant | BQ41: 1987 | BR41: 481076 | BS41: 22167 | BT41: 25236 | BU41: 10167 | BV41: 21984 | BW41: 0 | BX41: 37852 | BY41: 363671 | BZ41: =SUM(BS41:BY41) -> 481077 | CB41: 0.244 | CC41: =BQ41 -> 1987 | CD41: =(BR41-AV41)/AV41 -> -0.15105334 | CE41: =(BY41-AU41)/AU41 -> -0.15425349 | CH41: 1987 | CI41: 430000 | CJ41: 1116839 | CK41: =(CI41-P41)/P41 -> 0.18238738 | CL41: =(CJ41-AB41)/AB41 -> -0.24675545
A42: =N42 -> Grant | B42: =J42 -> 1988 | C42: =K42 -> 488070 | D42: =L42 -> 406805 | E42: =LN(D42/C42) -> -0.18212488 | F42: =A42 -> Grant | G42: =P42 -> 528467 | H42: =W42 -> 1535457.6 | I42: =LN(H42/G42) -> 1.0666033 | J42: 1988 | K42: 488070 | L42: 406805 | N42: =BP42 -> Grant | O42: =BQ42 -> 1988 | P42: =BY42 -> 528467 | Q42: =BR42 -> 1035111 | S42: =$Q45*S$2 -> 156199.8 | T42: =$Q46*T$2 -> 1181260.3 | U42: =$Q47*U$2 -> 194677.41 | V42: =$Q48*V$2 -> 3320.028 | W42: =SUM(S42:V42) -> 1535457.6 | X42: =$Q45*$S$2 -> 156199.8 | Y42: =$Q46*$T$2 -> 1181260.3 | Z42: =$Q47*$U$2 -> 194677.41 | AA42: =$Q48*$V$2 -> 3320.028 | AB42: =SUM(X42:AA42) -> 1535457.6 | AD42: Cass | AE42: 1988 | AF42: 488070 | AG42: =AS42 -> 685238 | AH42: =AG42/(AF42+AG42) -> 0.58402227 | AI42: =AF42+AG42 -> 1173308 | AJ42: =(AI42-BR42)/BR42 -> 0.13350935 | AK42: Cass | AL42: 1988 | AM42: 250953 | AN42: 4743 | AO42: 196360 | AP42: 96300 | AQ42: 30719 | AR42: 106162 | AS42: 685238 | AT42: =AS42/AV42 -> 0.58402227 | AU42: 488070 | AV42: 1173308 | AW42: =AS42/AV42 -> 0.58402227 | AX42: =AM42/AV42 -> 0.21388502 | AY42: =AO42/(AV42-AM42) -> 0.21288983 | AZ42: =AR42/(AV42-AM42-AO42-AQ42) -> 0.15269044 | BA42: =AS42/AV42 -> 0.58402227 | BB42: =AU42*BA42/(1-BA42) -> 685238 | BC42: 0.56 | BD42: =AX42/(SUM($AX42:$AZ42)) -> 0.36910755 | BE42: =AY42/(SUM($AX42:$AZ42)) -> 0.36739014 | BF42: =AZ42/(SUM($AX42:$AZ42)) -> 0.26350231 | BH42: 1988 | BI42: 1634560 | BJ42: 1788874.1 | BK42: 0.52253791 | BL42: 3423434.1 | BN42: =AT42 -> 0.58402227 | BP42: Grant | BQ42: 1988 | BR42: 1035111 | BS42: 296424 | BT42: 3964 | BU42: 1537 | BV42: 96892 | BW42: 0 | BX42: 107827 | BY42: 528467 | BZ42: =SUM(BS42:BY42) -> 1035111 | CB42: 0.489 | CC42: =BQ42 -> 1988 | CD42: =(BR42-AV42)/AV42 -> -0.11778408 | CE42: =(BY42-AU42)/AU42 -> 0.082768865 | CH42: 1988 | CI42: 488070 | CJ42: 406805 | CK42: =(CI42-P42)/P42 -> -0.076441859 | CL42: =(CJ42-AB42)/AB42 -> -0.73505943
A43: =N43 -> Grant | B43: =J43 -> 1989 | C43: =K43 -> 523657 | D43: =W43 -> 1593611 | E43: =LN(D43/C43) -> 1.1129209 | F43: =A43 -> Grant | G43: =P43 -> 739647 | H43: =W43 -> 1593611 | I43: =LN(H43/G43) -> 0.76758472 | J43: 1989 | K43: 523657 | L43: =NA() -> #N/A | N43: =BP43 -> Grant | O43: =BQ43 -> 1989 | P43: =BY43 -> 739647 | Q43: =BR43 -> 1094661 | S43: =$Q46*S$2 -> 167107.71 | T43: =$Q47*T$2 -> 1121233.7 | U43: =$Q48*U$2 -> 302601.69 | V43: =$Q49*V$2 -> 2667.8987 | W43: =SUM(S43:V43) -> 1593611 | X43: =$Q46*$S$2 -> 167107.71 | Y43: =$Q47*$T$2 -> 1121233.7 | Z43: =$Q48*$U$2 -> 302601.69 | AA43: =$Q49*$V$2 -> 2667.8987 | AB43: =SUM(X43:AA43) -> 1593611 | AE43: 1989 | AK43: Cass | AL43: 1989 | AM43: 256398 | AN43: 8017 | AO43: 25786 | AP43: 55544 | AQ43: 16769 | AR43: 37156 | AS43: 399670 | AT43: =AS43/AV43 -> 0.43093335 | AU43: 527782 | AV43: 927452 | AW43: =AS43/AV43 -> 0.43093335 | AX43: =AM43/AV43 -> 0.2764542 | AY43: =AO43/(AV43-AM43) -> 0.038426118 | AZ43: =AR43/(AV43-AM43-AO43-AQ43) -> 0.05911863 | BA43: =AS43/AV43 -> 0.43093335 | BB43: =AU43*BA43/(1-BA43) -> 399670 | BC43: 0.56 | BD43: =AX43/(SUM($AX43:$AZ43)) -> 0.73918443 | BE43: =AY43/(SUM($AX43:$AZ43)) -> 0.10274392 | BF43: =AZ43/(SUM($AX43:$AZ43)) -> 0.15807165 | BH43: 1989 | BI43: 1029563 | BJ43: 822368.74 | BK43: 0.44405996 | BL43: 1851931.7 | BN43: =AT43 -> 0.43093335 | BP43: Grant | BQ43: 1989 | BR43: 1094661 | BS43: 244269 | BT43: 6323 | BU43: 9749 | BV43: 55358 | BW43: 0 | BX43: 39315 | BY43: 739647 | BZ43: =SUM(BS43:BY43) -> 1094661 | CB43: 0.324 | CC43: =BQ43 -> 1989 | CD43: =(BR43-AV43)/AV43 -> 0.18028858 | CE43: =(BY43-AU43)/AU43 -> 0.40142521 | CH43: 1989
A44: =N44 -> Grant | B44: =J44 -> 1990 | C44: =K44 -> 736039 | D44: =W44 -> 2146403.2 | E44: =LN(D44/C44) -> 1.0702657 | F44: =A44 -> Grant | G44: =P44 -> 861972 | H44: =W44 -> 2146403.2 | I44: =LN(H44/G44) -> 0.91232599 | J44: 1990 | K44: 736039 | L44: =NA() -> #N/A | N44: =BP44 -> Grant | O44: =BQ44 -> 1990 | P44: =BY44 -> 861972 | Q44: =BR44 -> 1594885 | S44: =$Q47*S$2 -> 158616 | T44: =$Q48*T$2 -> 1742817.5 | U44: =$Q49*U$2 -> 243163.8 | V44: =$Q50*V$2 -> 1805.815 | W44: =SUM(S44:V44) -> 2146403.2 | X44: =$Q47*$S$2 -> 158616 | Y44: =$Q48*$T$2 -> 1742817.5 | Z44: =$Q49*$U$2 -> 243163.8 | AA44: =$R50*$V$2 -> 1805.815 | AB44: =SUM(X44:AA44) -> 2146403.2 | AE44: 1990 | AK44: Cass | AL44: 1990 | AM44: 437784 | AN44: 8274 | AO44: 1988 | AP44: 143511 | AQ44: 15719 | AR44: 127188 | AS44: 734464 | AT44: =AS44/AV44 -> 0.49435486 | AU44: 751239 | AV44: 1485702 | AW44: =AS44/AV44 -> 0.49435486 | AX44: =AM44/AV44 -> 0.29466474 | AY44: =AO44/(AV44-AM44) -> 0.001897095 | AZ44: =AR44/(AV44-AM44-AO44-AQ44) -> 0.1234582 | BA44: =AS44/AV44 -> 0.49435486 | BB44: =AU44*BA44/(1-BA44) -> 734464.98 | BC44: 0.57 | BD44: =AX44/(SUM($AX44:$AZ44)) -> 0.70154924 | BE44: =AY44/(SUM($AX44:$AZ44)) -> 0.0045166773 | BF44: =AZ44/(SUM($AX44:$AZ44)) -> 0.29393408 | BH44: 1990 | BI44: 1743112 | BJ44: 1884857.3 | BK44: 0.51953507 | BL44: 3627969.3 | BN44: =AT44 -> 0.49435486 | BP44: Grant | BQ44: 1990 | BR44: 1594885 | BS44: 451937 | BT44: 16682 | BU44: 4 | BV44: 144478 | BW44: 0 | BX44: 119812 | BY44: 861972 | BZ44: =SUM(BS44:BY44) -> 1594885 | CB44: 0.46 | CC44: =BQ44 -> 1990 | CD44: =(BR44-AV44)/AV44 -> 0.073489165 | CE44: =(BY44-AU44)/AU44 -> 0.14740049 | CH44: 1990
A45: =N45 -> Grant | B45: =J45 -> 1991 | C45: =K45 -> 790060 | D45: =W45 -> 1813267.3 | E45: =LN(D45/C45) -> 0.83077674 | F45: =A45 -> Grant | G45: =P45 -> 1106348 | H45: =W45 -> 1813267.3 | I45: =LN(H45/G45) -> 0.49406586 | J45: 1991 | K45: 790060 | L45: =NA() -> #N/A | N45: =BP45 -> Grant | O45: =BQ45 -> 1991 | P45: =BY45 -> 1106348 | Q45: =BR45 -> 1454169 | S45: =$Q48*S$2 -> 246548.74 | T45: =$Q49*T$2 -> 1400488.4 | U45: =$Q50*U$2 -> 164589.78 | V45: =$Q51*V$2 -> 1640.421 | W45: =SUM(S45:V45) -> 1813267.3 | X45: =$Q48*$S$2 -> 246548.74 | Y45: =$Q49*$T$2 -> 1400488.4 | Z45: =$R50*$U$2 -> 164589.78 | AA45: =$R51*$V$2 -> 1640.421 | AB45: =SUM(X45:AA45) -> 1813267.3 | AC45: For recruits | AE45: 1991 | AL45: 1991 | AT45: =BC45 -> 0.42 | BC45: 0.42 | BP45: Grant | BQ45: 1991 | BR45: 1454169 | BS45: 104533 | BT45: 54637 | BU45: 78 | BV45: 110837 | BW45: 0 | BX45: 77737 | BY45: 1106348 | BZ45: =SUM(BS45:BY45) -> 1454170 | CB45: 0.239 | CH45: 1991
A46: =N46 -> Grant | B46: =J46 -> 1992 | C46: =K46 -> 757025 | D46: =W46 -> 1301468.2 | E46: =LN(D46/C46) -> 0.54185204 | F46: =A46 -> Grant | G46: =P46 -> 1035859 | H46: =W46 -> 1301468.2 | I46: =LN(H46/G46) -> 0.228262 | J46: 1992 | K46: 757025 | L46: =NA() -> #N/A | N46: =BP46 -> Grant | O46: =BQ46 -> 1992 | P46: =BY46 -> 1035859 | Q46: =BR46 -> 1555718 | S46: =$Q49*S$2 -> 198120.93 | T46: =$Q50*T$2 -> 947945.65 | U46: =$Q51*U$2 -> 149515.05 | V46: =$Q52*V$2 -> 5886.6044 | W46: =SUM(S46:V46) -> 1301468.2 | X46: =$Q49*$S$2 -> 198120.93 | Y46: =$R50*$T$2 -> 947945.65 | Z46: =$R51*$U$2 -> 149515.05 | AA46: =$R52*$V$2 -> 5886.6044 | AB46: =SUM(X46:AA46) -> 1301468.2 | AC46: %dif, Haleys vs digitized | AE46: 1992 | AL46: 1992 | AT46: =BC46 -> 0.53 | BC46: 0.53 | BP46: Grant | BQ46: 1992 | BR46: 1555718 | BS46: 309541 | BT46: 48931 | BU46: 57 | BV46: 90015 | BW46: 0 | BX46: 71317 | BY46: 1035859 | BZ46: =SUM(BS46:BY46) -> 1555720 | CB46: 0.334 | CH46: 1992
A47: =N47 -> Grant | B47: =J47 -> 1993 | C47: =K47 -> 788831 | D47: =L47 -> 1361315 | E47: =LN(D47/C47) -> 0.54565432 | F47: =A47 -> Grant | G47: =P47 -> 985479 | H47: =W47 -> 1536216.2 | I47: =LN(H47/G47) -> 0.44394985 | J47: 1993 | K47: 788831 | L47: 1361315 | N47: =BP47 -> Grant | O47: =AE47 -> 1993 | P47: =BY47 -> 985479 | Q47: =BR47 -> 1476663 | S47: =$Q50*S$2 -> 134101.71 | T47: =$Q51*T$2 -> 861123.58 | U47: =$Q52*U$2 -> 536530.53 | V47: =$Q53*V$2 -> 4460.3967 | W47: =SUM(S47:V47) -> 1536216.2 | X47: =$R50*$S$2 -> 134101.71 | Y47: =$R51*$T$2 -> 861123.58 | Z47: =$R52*$U$2 -> 536530.53 | AA47: =$R53*$V$2 -> 4460.3967 | AB47: =SUM(X47:AA47) -> 1536216.2 | AC47: =(AB47-L47)/L47 -> 0.1284796 | AD47: Brittany | AE47: 1993 | AF47: 788831 | AG47: =AF47*AT47/(1-AT47) -> 854566.92 | AH47: =AG47/(AF47+AG47) -> 0.52 | AI47: =AF47+AG47 -> 1643397.9 | AJ47: =(AI47-BR47)/BR47 -> 0.11291332 | AL47: 1993 | AT47: =BC47 -> 0.52 | BC47: 0.52 | BP47: Grant | BQ47: 1993 | BR47: 1476663 | BS47: 250194 | BT47: 26665 | BU47: 28 | BV47: 98891 | BW47: 0 | BX47: 115406 | BY47: 985479 | BZ47: =SUM(BS47:BY47) -> 1476663 | CB47: 0.333 | CH47: 1993 | CI47: 788831 | CJ47: 1361315 | CK47: =(CI47-P47)/P47 -> -0.1995456 | CL47: =(CJ47-AB47)/AB47 -> -0.11385195
A48: =N48 -> Grant | B48: =J48 -> 1994 | C48: =P48 -> 1666079 | D48: =L48 -> 3442899 | E48: =LN(D48/C48) -> 0.72584089 | F48: =A48 -> Grant | G48: =P48 -> 1666079 | H48: =W48 -> 3619664.9 | I48: =LN(H48/G48) -> 0.77590848 | J48: 1994 | K48: =NA() -> #N/A | L48: 3442899 | N48: =BP48 -> Grant | O48: =BQ48 -> 1994 | P48: =BY48 -> 1666079 | Q48: =BR48 -> 2295288 | S48: =$Q51*S$2 -> 121819.37 | T48: =$Q52*T$2 -> 3090117.7 | U48: =$Q53*U$2 -> 406539.81 | V48: =$Q54*V$2 -> 1188.0071 | W48: =SUM(S48:V48) -> 3619664.9 | X48: =$R51*$S$2 -> 121819.37 | Y48: =$R52*$T$2 -> 3090117.7 | Z48: =$R53*$U$2 -> 406539.81 | AA48: =$R54*$V$2 -> 1188.0071 | AB48: =SUM(X48:AA48) -> 3619664.9 | AC48: =(AB48-L48)/L48 -> 0.051342162 | AD48: Brittany | AE48: 1994 | AH48: =AT48 -> 0.44 | AL48: 1994 | AT48: =BC48 -> 0.44 | BC48: 0.44 | BP48: Grant | BQ48: 1994 | BR48: 2295288 | BS48: 335201 | BT48: 24576 | BU48: 0 | BV48: 54975 | BW48: 0 | BX48: 214456 | BY48: 1666079 | BZ48: =SUM(BS48:BY48) -> 2295287 | CB48: 0.274 | CH48: 1994 | CV48: Digitized from DFO 2023 slide set
A49: =N49 -> Grant | B49: =J49 -> 1995 | C49: =P49 -> 1628542 | D49: =L49 -> 3112653 | E49: =LN(D49/C49) -> 0.64779028 | F49: =A49 -> Grant | G49: =P49 -> 1628542 | H49: =W49 -> 2891781.2 | I49: =LN(H49/G49) -> 0.57418751 | J49: 1995 | K49: =NA() -> #N/A | L49: 3112653 | N49: =BP49 -> Grant | O49: =AE49 -> 1995 | P49: =BY49 -> 1628542 | Q49: =BR49 -> 1844441 | R49: Brittany tot. stock | S49: =$Q52*$S$2 -> 437145.37 | T49: =$Q53*$T$2 -> 2341443.4 | U49: =$Q54*$U$2 -> 108280.09 | V49: =$Q55*$V$2 -> 4912.3558 | W49: =SUM(S49:V49) -> 2891781.2 | X49: =$R52*$S$2 -> 437145.37 | Y49: =$R53*$T$2 -> 2341443.4 | Z49: =$R54*$U$2 -> 108280.09 | AA49: =$R55*$V$2 -> 4912.3558 | AB49: =SUM(X49:AA49) -> 2891781.2 | AC49: =(AB49-L49)/L49 -> -0.07095934 | AD49: Brittany | AE49: 1995 | AH49: =AT49 -> 0.28 | AL49: 1995 | AT49: =BC49 -> 0.28 | BC49: 0.28 | BP49: Grant | BQ49: 1995 | BR49: 1844441 | BS49: 94747 | BT49: 2224 | BU49: 507 | BV49: 31940 | BW49: 0 | BX49: 86480 | BY49: 1628542 | BZ49: =SUM(BS49:BY49) -> 1844440 | CB49: 0.117 | CH49: 1995 | CT49: Year | CU49: total Run | CV49: spawners | CW49: catch | CX49: harvest rate | CZ49: %dif spawn | DA49: %dif hr
A50: Haley | B50: =J50 -> 1996 | C50: =K50 -> 1186180 | D50: =L50 -> 1431408 | E50: =LN(D50/C50) -> 0.18792052 | F50: Murdoch | G50: =P50 -> 1186180 | H50: =W50 -> 1406508.4 | I50: =LN(H50/G50) -> 0.17037224 | J50: 1996 | K50: 1186180 | L50: 1431408 | N50: =AD50 -> Brittany | O50: =AE50 -> 1996 | P50: =AF50 -> 1186180 | Q50: =AI50 -> 1248442.9 | R50: =Q50 -> 1248442.9 | S50: =$Q53*$S$2 -> 331233.71 | T50: =$Q54*$T$2 -> 623633.15 | U50: =$Q55*$U$2 -> 447733.31 | V50: =$Q56*$V$2 -> 3908.2061 | W50: =SUM(S50:V50) -> 1406508.4 | X50: =$R53*$S$2 -> 331233.71 | Y50: =$R54*$T$2 -> 623633.15 | Z50: =$R55*$U$2 -> 447733.31 | AA50: =$R56*$V$2 -> 3908.2061 | AB50: =SUM(X50:AA50) -> 1406508.4 | AC50: =(AB50-L50)/L50 -> -0.017395197 | AD50: Brittany | AE50: 1996 | AF50: 1186180 | AG50: =AI50-AF50 -> 62262.946 | AH50: =AG50/AI50 -> 0.04987248 | AI50: 1248442.9 | AJ50: =(AI50-BR50)/BR50 -> 0.4084213 | AL50: 1996 | AT50: =BC50 -> 0.27 | BC50: 0.27 | BP50: Grant | BQ50: 1996 | BR50: 886413 | BS50: 24816 | BT50: 0 | BU50: 0 | BV50: 81 | BW50: 0 | BX50: 16175 | BY50: 845342 | BZ50: =SUM(BS50:BY50) -> 886414 | CB50: 0.046 | CH50: 1996 | CI50: 1186180 | CJ50: 1431408 | CK50: =(CI50-P50)/P50 -> 0 | CL50: =(CJ50-AB50)/AB50 -> 0.017703147 | CT50: 1996 | CU50: 1253503.3 | CV50: 1123652.9 | CW50: =CU50-CV50 -> 129850.39 | CX50: =CW50/CU50 -> 0.10358999 | CZ50: =(K50-CV50)/CU50 -> 0.049881843 | DA50: =(AH50-CX50)/CX50 -> -0.51855887
...

Sheet SR + catch data Haley
A1: Source | B1: Brood year | C1: Spawners (D) | D1: Total stock | E1: Recruits | F1: SpawnC | G1: RecruitC | H1: lnRSC | I1: CatchC | J1: HR | K1: =covariates!R9 -> spawners | L1: =covariates!T9 -> smolt.sst | M1: =covariates!V9 -> SSLs, control stopped 1970 | N1: =covariates!U9 -> NPGO | O1: =covariates!W9 -> adult.sst | P1: =covariates!X9 -> PDO adult | Q1: =H1 -> lnRSC | R1: Year | S1: alpha(y)
A2: Cass | B2: 1951 | C2: ='Orig data'!C5 -> 171725 | D2: ='Orig data'!Q5 -> 1187739 | E2: ='Orig data'!D5 -> 498986 | F2: =C2/1000 -> 171.725 | G2: =E2/1000 -> 498.986 | H2: =LN(E2/C2) -> 1.0666837 | I2: =D2-C2 -> 1016014 | J2: =I2/D2 -> 0.85541857 | K2: =covariates!R11 -> 171725 | L2: =covariates!T11 -> -1.4648119 | M2: =covariates!V11 -> 0.21616787 | N2: =covariates!U11 -> -1.0984671 | O2: =covariates!W11 -> -1.1106467 | P2: =covariates!X11 -> -2.2405166 | Q2: =H2 -> 1.0666837 | R2: =B2 -> 1951 | S2: =$AX$23+K2*$AX$24+L2*$AX$25+M2*$AX$26 -> 1.0737449
A3: Cass | B3: 1952 | C3: ='Orig data'!C6 -> 176250 | D3: ='Orig data'!Q6 -> 927000 | E3: ='Orig data'!D6 -> 283055 | F3: =C3/1000 -> 176.25 | G3: =E3/1000 -> 283.055 | H3: =LN(E3/C3) -> 0.47373778 | I3: =D3-C3 -> 750750 | J3: =I3/D3 -> 0.80987055 | K3: =covariates!R12 -> 176250 | L3: =covariates!T12 -> -0.66139705 | M3: =covariates!V12 -> 0.16409794 | N3: =covariates!U12 -> 0.85361449 | O3: =covariates!W12 -> -0.40960074 | P3: =covariates!X12 -> -1.24959 | Q3: =H3 -> 0.47373778 | R3: =B3 -> 1952 | S3: =$AX$23+K3*$AX$24+L3*$AX$25+M3*$AX$26 -> 0.979765
A4: Grant | B4: 1953 | C4: ='Orig data'!C7 -> 137225 | D4: ='Orig data'!Q7 -> 918122 | E4: ='Orig data'!D7 -> 312122 | F4: =C4/1000 -> 137.225 | G4: =E4/1000 -> 312.122 | H4: =LN(E4/C4) -> 0.82177222 | I4: =D4-C4 -> 780897 | J4: =I4/D4 -> 0.85053729 | K4: =covariates!R13 -> 137625 | L4: =covariates!T13 -> -1.1472717 | M4: =covariates!V13 -> -0.15610451 | N4: =covariates!U13 -> 0.90303427 | O4: =covariates!W13 -> 0.94352578 | P4: =covariates!X13 -> 1.0113249 | Q4: =H4 -> 0.82177222 | R4: =B4 -> 1953 | S4: =$AX$23+K4*$AX$24+L4*$AX$25+M4*$AX$26 -> 1.1020316
A5: Grant | B5: 1954 | C5: ='Orig data'!C8 -> 86375 | D5: ='Orig data'!Q8 -> 1096517 | E5: ='Orig data'!D8 -> 504589 | F5: =C5/1000 -> 86.375 | G5: =E5/1000 -> 504.589 | H5: =LN(E5/C5) -> 1.765046 | I5: =D5-C5 -> 1010142 | J5: =I5/D5 -> 0.92122785 | K5: =covariates!R14 -> 86375 | L5: =covariates!T14 -> -1.4571603 | M5: =covariates!V14 -> -0.4738288 | N5: =covariates!U14 -> 0.038188016 | O5: =covariates!W14 -> 0.8742115 | P5: =covariates!X14 -> 1.0277654 | Q5: =H5 -> 1.765046 | R5: =B5 -> 1954 | S5: =$AX$23+K5*$AX$24+L5*$AX$25+M5*$AX$26 -> 1.2082923
A6: Grant | B6: 1955 | C6: ='Orig data'!C9 -> 110500 | D6: ='Orig data'!Q9 -> 397099 | E6: ='Orig data'!D9 -> 592568 | F6: =C6/1000 -> 110.5 | G6: =E6/1000 -> 592.568 | H6: =LN(E6/C6) -> 1.6794501 | I6: =D6-C6 -> 286599 | J6: =I6/D6 -> 0.72173186 | K6: =covariates!R15 -> 110500 | L6: =covariates!T15 -> -1.6331464 | M6: =covariates!V15 -> -0.63243612 | N6: =covariates!U15 -> -0.15949113 | O6: =covariates!W15 -> -0.35887996 | P6: =covariates!X15 -> 1.0857902 | Q6: =H6 -> 1.6794501 | R6: =B6 -> 1955 | S6: =$AX$23+K6*$AX$24+L6*$AX$25+M6*$AX$26 -> 1.2402737
A7: Grant | B7: 1956 | C7: ='Orig data'!C10 -> 32925 | D7: ='Orig data'!Q10 -> 282627 | E7: ='Orig data'!D10 -> 518932 | F7: =C7/1000 -> 32.925 | G7: =E7/1000 -> 518.932 | H7: =LN(E7/C7) -> 2.7575406 | I7: =D7-C7 -> 249702 | J7: =I7/D7 -> 0.8835037 | K7: =covariates!R16 -> 32950 | L7: =covariates!T16 -> -0.93685356 | M7: =covariates!V16 -> -0.61854863 | N7: =covariates!U16 -> -1.3702759 | O7: =covariates!W16 -> -0.59361318 | P7: =covariates!X16 -> 0.59134867 | Q7: =H7 -> 2.7575406 | R7: =B7 -> 1956 | S7: =$AX$23+K7*$AX$24+L7*$AX$25+M7*$AX$26 -> 1.1895366 | AW7: SUMMARY OUTPUT
A8: Grant | B8: 1957 | C8: ='Orig data'!C11 -> 84630 | D8: ='Orig data'!Q11 -> 308363 | E8: ='Orig data'!D11 -> 353281 | F8: =C8/1000 -> 84.63 | G8: =E8/1000 -> 353.281 | H8: =LN(E8/C8) -> 1.428975 | I8: =D8-C8 -> 223733 | J8: =I8/D8 -> 0.72555073 | K8: =covariates!R17 -> 84655 | L8: =covariates!T17 -> 0.79622698 | M8: =covariates!V17 -> -0.6302244 | N8: =covariates!U17 -> -0.45600984 | O8: =covariates!W17 -> 0.12052565 | P8: =covariates!X17 -> -0.78767908 | Q8: =H8 -> 1.428975 | R8: =B8 -> 1957 | S8: =$AX$23+K8*$AX$24+L8*$AX$25+M8*$AX$26 -> 0.95299088
A9: Grant | B9: 1958 | C9: ='Orig data'!C12 -> 89375 | D9: ='Orig data'!Q12 -> 559829 | E9: ='Orig data'!D12 -> 302174 | F9: =C9/1000 -> 89.375 | G9: =E9/1000 -> 302.174 | H9: =LN(E9/C9) -> 1.218162 | I9: =D9-C9 -> 470454 | J9: =I9/D9 -> 0.84035304 | K9: =covariates!R18 -> 89400 | L9: =covariates!T18 -> -0.16021923 | M9: =covariates!V18 -> -0.64877422 | N9: =covariates!U18 -> -0.35717027 | O9: =covariates!W18 -> 0.49073089 | P9: =covariates!X18 -> 0.023031265 | Q9: =H9 -> 1.218162 | R9: =B9 -> 1958 | S9: =$AX$23+K9*$AX$24+L9*$AX$25+M9*$AX$26 -> 1.0711114 | AW9: Regression Statistics
